<?xml version="1.0" ?>
<!-- =================================================================================== -->
<!-- |    This document was autogenerated by xacro from gypsy.urdf.xacro               | -->
<!-- |    EDITING THIS FILE BY HAND IS NOT RECOMMENDED                                 | -->
<!-- =================================================================================== -->
<robot name="gypsy">
  <link name="panda_link0">
    <visual>
      <origin rpy="0 0 0" xyz="0 0 0"/>
      <geometry>
        <mesh filename="file:///home/junglator/pandora_ws/install/gypsy_robot/share/gypsy_robot/meshes/panda_arm/link0.obj"/>
      </geometry>
    </visual>
    <collision>
      <origin rpy="0 0 0" xyz="0 0 0"/>
      <geometry>
        <mesh filename="file:///home/junglator/pandora_ws/install/gypsy_robot/share/gypsy_robot/meshes/panda_arm/link0.obj"/>
      </geometry>
    </collision>
    <inertial>
      <origin rpy="0 0 0" xyz="-0.041018 -0.00014 0.049974"/>
      <mass value="0.629769"/>
      <inertia ixx="0.00315" ixy="8.2904E-07" ixz="0.00015" iyy="0.00388" iyz="8.2299E-06" izz="0.004285"/>
    </inertial>
  </link>
  <link name="panda_link1">
    <visual>
      <origin rpy="0 0 0" xyz="0 0 0"/>
      <geometry>
        <mesh filename="file:///home/junglator/pandora_ws/install/gypsy_robot/share/gypsy_robot/meshes/panda_arm/link1.obj"/>
      </geometry>
    </visual>
    <collision>
      <origin rpy="0 0 0" xyz="0 0 0"/>
      <geometry>
        <mesh filename="file:///home/junglator/pandora_ws/install/gypsy_robot/share/gypsy_robot/meshes/panda_arm/link1.obj"/>
      </geometry>
    </collision>
    <inertial>
      <origin rpy="0 0 0" xyz="0.0082121602797146209 -0.026532335711888823 -0.047138121275696603"/>
      <mass value="4.9706751871147938"/>
      <inertia ixx="0.70141461794089599" ixy="-0.00063981642154032682" ixz="0.0078364148804466946" iyy="0.70480134490761892" iyz="0.01074540620106503" izz="0.010111109106129931"/>
    </inertial>
  </link>
  <link name="panda_link2">
    <visual>
      <origin rpy="0 0 0" xyz="0 0 0"/>
      <geometry>
        <mesh filename="file:///home/junglator/pandora_ws/install/gypsy_robot/share/gypsy_robot/meshes/panda_arm/link2.obj"/>
      </geometry>
    </visual>
    <collision>
      <origin rpy="0 0 0" xyz="0 0 0"/>
      <geometry>
        <mesh filename="file:///home/junglator/pandora_ws/install/gypsy_robot/share/gypsy_robot/meshes/panda_arm/link2.obj"/>
      </geometry>
    </collision>
    <inertial>
      <origin rpy="0 0 0" xyz="-0.0088444802449167883 -0.027531520310653038 -0.00055850347148591131"/>
      <mass value="0.64712411452542207"/>
      <inertia ixx="0.012028228395010528" ixy="-0.005176957021186453" ixz="0.028416723889140006" iyy="0.034001000715476563" iyz="-0.0034872992153212263" izz="0.026005490424668338"/>
    </inertial>
  </link>
  <link name="panda_link3">
    <visual>
      <origin rpy="0 0 0" xyz="0 0 0"/>
      <geometry>
        <mesh filename="file:///home/junglator/pandora_ws/install/gypsy_robot/share/gypsy_robot/meshes/panda_arm/link3.obj"/>
      </geometry>
    </visual>
    <collision>
      <origin rpy="0 0 0" xyz="0 0 0"/>
      <geometry>
        <mesh filename="file:///home/junglator/pandora_ws/install/gypsy_robot/share/gypsy_robot/meshes/panda_arm/link3.obj"/>
      </geometry>
    </collision>
    <inertial>
      <origin rpy="0 0 0" xyz="0.028340188017725303 0.037617533422114727 -0.067208806995820797"/>
      <mass value="3.2283417206016849"/>
      <inertia ixx="0.035865608781665073" ixy="-0.0048981742215283711" ixz="-0.01683647440270046" iyy="0.041062395573147469" iyz="-0.012957871374295925" izz="0.0072954180594979098"/>
    </inertial>
  </link>
  <link name="panda_link4">
    <visual>
      <origin rpy="0 0 0" xyz="0 0 0"/>
      <geometry>
        <mesh filename="file:///home/junglator/pandora_ws/install/gypsy_robot/share/gypsy_robot/meshes/panda_arm/link4.obj"/>
      </geometry>
    </visual>
    <collision>
      <origin rpy="0 0 0" xyz="0 0 0"/>
      <geometry>
        <mesh filename="file:///home/junglator/pandora_ws/install/gypsy_robot/share/gypsy_robot/meshes/panda_arm/link4.obj"/>
      </geometry>
    </collision>
    <inertial>
      <origin rpy="0 0 0" xyz="-0.052863658713578371 0.10286796966271235 0.027230575794129856"/>
      <mass value="3.5877058164189872"/>
      <inertia ixx="0.023713305935381724" ixy="0.019494904018681623" ixz="-0.00041806758858047981" iyy="0.016777579582937466" iyz="0.0073688153189040975" izz="0.03323445513208665"/>
    </inertial>
  </link>
  <link name="panda_link5">
    <visual>
      <origin rpy="0 0 0" xyz="0 0 0"/>
      <geometry>
        <mesh filename="file:///home/junglator/pandora_ws/install/gypsy_robot/share/gypsy_robot/meshes/panda_arm/link5.obj"/>
      </geometry>
    </visual>
    <collision>
      <origin rpy="0 0 0" xyz="0 0 0"/>
      <geometry>
        <mesh filename="file:///home/junglator/pandora_ws/install/gypsy_robot/share/gypsy_robot/meshes/panda_arm/link5.obj"/>
      </geometry>
    </collision>
    <inertial>
      <origin rpy="0 0 0" xyz="-0.0081910657546574537 0.042932437976240877 -0.03621309770351528"/>
      <mass value="1.2258764841419181"/>
      <inertia ixx="0.039833353765046244" ixy="-0.0041636653470603583" ixz="-0.0057791872240629304" iyy="0.027963868212344253" iyz="0.0057981330723796617" izz="0.0058527143406942126"/>
    </inertial>
  </link>
  <link name="panda_link6">
    <visual>
      <origin rpy="0 0 0" xyz="0 0 0"/>
      <geometry>
        <mesh filename="file:///home/junglator/pandora_ws/install/gypsy_robot/share/gypsy_robot/meshes/panda_arm/link6.obj"/>
      </geometry>
    </visual>
    <collision>
      <origin rpy="0 0 0" xyz="0 0 0"/>
      <geometry>
        <mesh filename="file:///home/junglator/pandora_ws/install/gypsy_robot/share/gypsy_robot/meshes/panda_arm/link6.obj"/>
      </geometry>
    </collision>
    <inertial>
      <origin rpy="0 0 0" xyz="0.060550072294159214 -0.013508438365027796 -0.014648696562393272"/>
      <mass value="1.6660195957719575"/>
      <inertia ixx="0.0018946535529745841" ixy="3.0085693236067733e-05" ixz="-0.0014917301754574759" iyy="0.0059333708668997337" iyz="0.001150006504840946" izz="0.0039230158812056833"/>
    </inertial>
  </link>
  <link name="panda_link7">
    <visual>
      <origin rpy="0 0 0" xyz="0 0 0"/>
      <geometry>
        <mesh filename="file:///home/junglator/pandora_ws/install/gypsy_robot/share/gypsy_robot/meshes/panda_arm/link7.obj"/>
      </geometry>
    </visual>
    <collision>
      <origin rpy="0 0 0" xyz="0 0 0"/>
      <geometry>
        <mesh filename="file:///home/junglator/pandora_ws/install/gypsy_robot/share/gypsy_robot/meshes/panda_arm/link7.obj"/>
      </geometry>
    </collision>
    <inertial>
      <origin rpy="0 0 0" xyz="0.0084850731223620312 -0.00063346827849231481 0.061428526086978817"/>
      <mass value="0.73598318978014388"/>
      <inertia ixx="0.0096273165930081117" ixy="0.0011836273982315374" ixz="0.0021412918431209403" iyy="0.011335955410605407" iyz="-0.000625294249958001" izz="0.0063944769299665851"/>
    </inertial>
  </link>
  <link name="panda_link8"/>
  <link name="hand">
    <inertial>
      <mass value="0.73"/>
      <origin rpy="0 0 0" xyz="0 0.0015244 0.0275912"/>
      <inertia ixx="0.00278560230025" ixy="0.0" ixz="0.0" iyy="0.000400033405336" iyz="0.0" izz="0.00256378041832"/>
    </inertial>
    <visual>
      <origin rpy="0 0 0" xyz="0 0 0"/>
      <geometry>
        <mesh filename="file:///home/junglator/pandora_ws/install/gypsy_robot/share/gypsy_robot/meshes/panda_arm/hand.obj"/>
      </geometry>
      <material name="">
        <color rgba="1 1 1 1"/>
      </material>
    </visual>
    <collision>
      <origin rpy="0 0 0" xyz="0 0 0"/>
      <geometry>
        <mesh filename="file:///home/junglator/pandora_ws/install/gypsy_robot/share/gypsy_robot/meshes/panda_arm/hand.obj"/>
      </geometry>
    </collision>
  </link>
  <link name="leftfinger">
    <inertial>
      <mass value="0.1"/>
      <origin rpy="0 0 0" xyz="0 0.0145644 0.0227941"/>
      <inertia ixx="3.01220925051e-05" ixy="0.0" ixz="0.0" iyy="2.95873808038e-05" iyz="0.0" izz="6.95125211657e-06"/>
    </inertial>
    <visual>
      <origin rpy="0 0 0" xyz="0 0 0"/>
      <geometry>
        <mesh filename="file:///home/junglator/pandora_ws/install/gypsy_robot/share/gypsy_robot/meshes/panda_arm/finger.obj"/>
      </geometry>
      <material name="">
        <color rgba="1 1 1 1"/>
      </material>
    </visual>
    <collision>
      <origin rpy="0 0 0" xyz="0 0 0"/>
      <geometry>
        <mesh filename="file:///home/junglator/pandora_ws/install/gypsy_robot/share/gypsy_robot/meshes/panda_arm/finger.obj"/>
      </geometry>
    </collision>
  </link>
  <link name="rightfinger">
    <inertial>
      <mass value="0.1"/>
      <origin rpy="0 0 3.1415926535897931" xyz="0 0.0145644 0.0227941"/>
      <inertia ixx="3.01220925051e-05" ixy="0.0" ixz="0.0" iyy="2.95873808038e-05" iyz="0.0" izz="6.95125211657e-06"/>
    </inertial>
    <visual>
      <origin rpy="0 0 3.1415926535897931" xyz="0 0 0"/>
      <geometry>
        <mesh filename="file:///home/junglator/pandora_ws/install/gypsy_robot/share/gypsy_robot/meshes/panda_arm/finger.obj"/>
      </geometry>
      <material name="">
        <color rgba="1 1 1 1"/>
      </material>
    </visual>
    <collision>
      <origin rpy="0 0 3.1415926535897931" xyz="0 0 0"/>
      <geometry>
        <mesh filename="file:///home/junglator/pandora_ws/install/gypsy_robot/share/gypsy_robot/meshes/panda_arm/finger.obj"/>
      </geometry>
    </collision>
  </link>
  <!--JOINTS-->
  <joint name="panda_joint1" type="revolute">
    <safety_controller k_position="100.0" k_velocity="40.0" soft_lower_limit="-2.8973" soft_upper_limit="2.8973"/>
    <origin rpy="0 0 0" xyz="0 0 0.333"/>
    <parent link="panda_link0"/>
    <child link="panda_link1"/>
    <axis xyz="0 0 1"/>
    <limit acceleration="15" effort="87" lower="-2.9671" upper="2.9671" velocity="2.5"/>
    <dynamics D="1" K="7000" damping="0.003" friction="0.0" mu_coulomb="0" mu_viscous="16"/>
  </joint>
  <joint name="panda_joint2" type="revolute">
    <safety_controller k_position="100.0" k_velocity="40.0" soft_lower_limit="-1.7628" soft_upper_limit="1.7628"/>
    <origin rpy="-1.5707963267948966 0 0" xyz="0 0 0"/>
    <parent link="panda_link1"/>
    <child link="panda_link2"/>
    <axis xyz="0 0 1"/>
    <limit acceleration="7.5" effort="87" lower="-1.8326" upper="1.8326" velocity="2.5"/>
    <dynamics D="1" K="7000" damping="0.003" friction="0.0" mu_coulomb="0" mu_viscous="16"/>
  </joint>
  <joint name="panda_joint3" type="revolute">
    <safety_controller k_position="100.0" k_velocity="40.0" soft_lower_limit="-2.8973" soft_upper_limit="2.8973"/>
    <origin rpy="1.5707963267948966 0 0" xyz="0 -0.316 0"/>
    <parent link="panda_link2"/>
    <child link="panda_link3"/>
    <axis xyz="0 0 1"/>
    <limit acceleration="12.5" effort="87" lower="-2.9671" upper="2.9671" velocity="2.5"/>
    <dynamics D="1" K="7000" damping="0.003" friction="0.0" mu_coulomb="0" mu_viscous="16"/>
  </joint>
  <joint name="panda_joint4" type="revolute">
    <safety_controller k_position="100.0" k_velocity="40.0" soft_lower_limit="-3.0718" soft_upper_limit="-0.0698"/>
    <origin rpy="1.5707963267948966 0 0" xyz="0.0825 0 0"/>
    <parent link="panda_link3"/>
    <child link="panda_link4"/>
    <axis xyz="0 0 1"/>
    <limit acceleration="12.5" effort="87" lower="-3.1416" upper="-0.4" velocity="2.5"/>
    <dynamics D="1" K="7000" damping="0.003" friction="0.0" mu_coulomb="0" mu_viscous="16"/>
  </joint>
  <joint name="panda_joint5" type="revolute">
    <safety_controller k_position="100.0" k_velocity="40.0" soft_lower_limit="-2.8973" soft_upper_limit="2.8973"/>
    <origin rpy="-1.5707963267948966 0 0" xyz="-0.0825 0.384 0"/>
    <parent link="panda_link4"/>
    <child link="panda_link5"/>
    <axis xyz="0 0 1"/>
    <limit acceleration="15" effort="12" lower="-2.9671" upper="2.9671" velocity="3"/>
    <dynamics D="1" K="7000" damping="0.003" friction="0.0" mu_coulomb="0" mu_viscous="16"/>
  </joint>
  <joint name="panda_joint6" type="revolute">
    <safety_controller k_position="100.0" k_velocity="40.0" soft_lower_limit="-0.0175" soft_upper_limit="3.7525"/>
    <origin rpy="1.5707963267948966 0 0" xyz="0 0 0"/>
    <parent link="panda_link5"/>
    <child link="panda_link6"/>
    <axis xyz="0 0 1"/>
    <limit acceleration="20" effort="12" lower="-0.0873" upper="3.8223" velocity="3"/>
    <dynamics D="1" K="7000" damping="0.003" friction="0.0" mu_coulomb="0" mu_viscous="16"/>
  </joint>
  <joint name="panda_joint7" type="revolute">
    <safety_controller k_position="100.0" k_velocity="40.0" soft_lower_limit="-2.8973" soft_upper_limit="2.8973"/>
    <origin rpy="1.5707963267948966 0 0" xyz="0.088 0 0"/>
    <parent link="panda_link6"/>
    <child link="panda_link7"/>
    <axis xyz="0 0 1"/>
    <limit acceleration="20" effort="12" lower="-2.9671" upper="2.9671" velocity="3"/>
    <dynamics D="1" K="7000" damping="0.003" friction="0.0" mu_coulomb="0" mu_viscous="16"/>
  </joint>
  <joint name="panda_joint8" type="fixed">
    <origin rpy="0 0 0" xyz="0 0 0.107"/>
    <parent link="panda_link7"/>
    <child link="panda_link8"/>
    <axis xyz="0 0 0"/>
  </joint>
  <joint name="panda_hand_joint" type="fixed">
    <parent link="panda_link8"/>
    <child link="hand"/>
    <origin rpy="0 0 -0.785398163397" xyz="0 0 -0.05"/>
  </joint>
  <joint name="finger_joint1" type="prismatic">
    <parent link="hand"/>
    <child link="leftfinger"/>
    <origin rpy="0 0 0" xyz="0 0 0.0584"/>
    <axis xyz="0 1 0"/>
    <limit effort="20" lower="-0.001" upper="0.04" velocity="0.3"/>
    <dynamics damping="3.0" friction="0.4"/>
  </joint>
  <joint name="finger_joint2" type="prismatic">
    <parent link="hand"/>
    <child link="rightfinger"/>
    <origin rpy="0 0 0" xyz="0 0 0.0584"/>
    <axis xyz="0 -1 0"/>
    <limit effort="20" lower="-0.001" upper="0.04" velocity="0.3"/>
    <dynamics damping="3.0" friction="0.4"/>
  </joint>
  <material name="panda_white">
    <color rgba="1. 1. 1. 1."/>
  </material>
  <material name="dark_grey">
    <color rgba="0.2 0.2 0.2 1.0"/>
  </material>
  <material name="light_grey">
    <color rgba="0.4 0.4 0.4 1.0"/>
  </material>
  <material name="red">
    <color rgba="0.8 0.0 0.0 1.0"/>
  </material>
  <material name="white">
    <color rgba="0.9 0.9 0.9 1.0"/>
  </material>
  <material name="black">
    <color rgba="0.15 0.15 0.15 1.0"/>
  </material>
  <link name="chassis">
    <visual>
      <origin rpy="0 0 0" xyz="0 0 0"/>
      <geometry>
        <mesh filename="file:///home/junglator/pandora_ws/install/gypsy_robot/share/gypsy_robot/meshes/mobile_bot/chassis_o.obj"/>
      </geometry>
      <material name="dark_grey"/>
    </visual>
    <collision>
      <origin xyz="0 0 0"/>
      <geometry>
        <mesh filename="file:///home/junglator/pandora_ws/install/gypsy_robot/share/gypsy_robot/meshes/mobile_bot/chassis_o.obj"/>
      </geometry>
      <material name="dark_grey"/>
    </collision>
    <inertial>
      <origin rpy="0 0 0" xyz="0 0 0"/>
      <mass value="30.00"/>
      <!--calcuated on the basis of dimension-->
      <inertia ixx="1.7755" ixy="0.00" ixz="0.00" iyy="1.40" iyz="0.00" izz="2.825"/>
    </inertial>
  </link>
  <link name="left_front_wheel">
    <visual>
      <origin rpy="0 0 0" xyz="0 0 0"/>
      <geometry>
        <mesh filename="file:///home/junglator/pandora_ws/install/gypsy_robot/share/gypsy_robot/meshes/mobile_bot/Wheel_Left.obj" scale="0.1 0.1 0.1"/>
      </geometry>
      <material name="black"/>
    </visual>
    <collision>
      <origin rpy="0 0 0" xyz="0 0 0"/>
      <geometry>
        <mesh filename="file:///home/junglator/pandora_ws/install/gypsy_robot/share/gypsy_robot/meshes/mobile_bot/Wheel_Left.obj" scale="0.1 0.1 0.1"/>
      </geometry>
      <material name="black"/>
    </collision>
    <inertial>
      <origin rpy="0 0 0" xyz="0 0 0"/>
      <mass value="0.329"/>
      <inertia ixx="0.0000129" ixy="0.00" ixz="0.00" iyy="0.000086529" iyz="0.0" izz="0.000086529"/>
    </inertial>
  </link>
  <link name="left_rear_wheel">
    <visual>
      <origin rpy="0 0 0" xyz="0 0 0"/>
      <geometry>
        <mesh filename="file:///home/junglator/pandora_ws/install/gypsy_robot/share/gypsy_robot/meshes/mobile_bot/Wheel_Left.obj" scale="0.1 0.1 0.1"/>
      </geometry>
      <material name="black"/>
    </visual>
    <collision>
      <origin rpy="0 0 0" xyz="0 0 0"/>
      <geometry>
        <mesh filename="file:///home/junglator/pandora_ws/install/gypsy_robot/share/gypsy_robot/meshes/mobile_bot/Wheel_Left.obj" scale="0.1 0.1 0.1"/>
      </geometry>
      <material name="black"/>
    </collision>
    <inertial>
      <origin rpy="0 0 0" xyz="0 0 0"/>
      <mass value="0.329"/>
      <inertia ixx="0.0000129" ixy="0.00" ixz="0.00" iyy="0.000086529" iyz="0.0" izz="0.000086529"/>
    </inertial>
  </link>
  <link name="right_front_wheel">
    <visual>
      <origin rpy="0 0 0" xyz="0 0 0"/>
      <geometry>
        <mesh filename="file:///home/junglator/pandora_ws/install/gypsy_robot/share/gypsy_robot/meshes/mobile_bot/Wheel_Right.obj" scale="0.1 0.1 0.1"/>
      </geometry>
      <material name="black"/>
    </visual>
    <collision>
      <origin rpy="0 0 0" xyz="0 0 0"/>
      <geometry>
        <mesh filename="file:///home/junglator/pandora_ws/install/gypsy_robot/share/gypsy_robot/meshes/mobile_bot/Wheel_Right.obj" scale="0.1 0.1 0.1"/>
      </geometry>
      <material name="black"/>
    </collision>
    <inertial>
      <origin rpy="0 0 0" xyz="0 0 0"/>
      <mass value="0.329"/>
      <inertia ixx="0.0000129" ixy="0.00" ixz="0.00" iyy="0.000086529" iyz="0.0" izz="0.000086529"/>
    </inertial>
  </link>
  <link name="right_rear_wheel">
    <visual>
      <origin rpy="0 0 0" xyz="0 0 0"/>
      <geometry>
        <mesh filename="file:///home/junglator/pandora_ws/install/gypsy_robot/share/gypsy_robot/meshes/mobile_bot/Wheel_Right.obj" scale="0.1 0.1 0.1"/>
      </geometry>
      <material name="black"/>
    </visual>
    <collision>
      <origin rpy="0 0 0" xyz="0 0 0"/>
      <geometry>
        <mesh filename="file:///home/junglator/pandora_ws/install/gypsy_robot/share/gypsy_robot/meshes/mobile_bot/Wheel_Right.obj" scale="0.1 0.1 0.1"/>
      </geometry>
      <material name="black"/>
    </collision>
    <inertial>
      <origin rpy="0 0 0" xyz="0 0 0"/>
      <mass value="0.329"/>
      <inertia ixx="0.0000129" ixy="0.00" ixz="0.00" iyy="0.000086529" iyz="0.0" izz="0.000086529"/>
    </inertial>
  </link>
  <link name="bin_red">
    <visual>
      <origin rpy="0 0 0" xyz="0 0 0"/>
      <geometry>
        <mesh filename="file:///home/junglator/pandora_ws/install/gypsy_robot/share/gypsy_robot/meshes/mobile_bot/bin.obj"/>
      </geometry>
      <material name="red"/>
    </visual>
    <collision>
      <origin rpy="0 0 0" xyz="0 0 0"/>
      <geometry>
        <mesh filename="file:///home/junglator/pandora_ws/install/gypsy_robot/share/gypsy_robot/meshes/mobile_bot/bin.obj"/>
      </geometry>
      <material name="red"/>
    </collision>
    <inertial>
      <origin rpy="0 0 0" xyz="0 0 0"/>
      <mass value="0.200"/>
      <inertia ixx="0.004" ixy="0.00" ixz="0.00" iyy="0.004" iyz="0.0" izz="0.004"/>
    </inertial>
  </link>
  <link name="bin_green">
    <visual>
      <origin rpy="0 0 0" xyz="0 0 0"/>
      <geometry>
        <mesh filename="file:///home/junglator/pandora_ws/install/gypsy_robot/share/gypsy_robot/meshes/mobile_bot/bin.obj"/>
      </geometry>
      <material name="red"/>
    </visual>
    <collision>
      <origin rpy="0 0 0" xyz="0 0 0"/>
      <geometry>
        <mesh filename="file:///home/junglator/pandora_ws/install/gypsy_robot/share/gypsy_robot/meshes/mobile_bot/bin.obj"/>
      </geometry>
      <material name="red"/>
    </collision>
    <inertial>
      <origin rpy="0 0 0" xyz="0 0 0"/>
      <mass value="0.200"/>
      <inertia ixx="0.004" ixy="0.00" ixz="0.00" iyy="0.004" iyz="0.0" izz="0.004"/>
    </inertial>
  </link>
  <link name="camera_one">
    <visual>
      <origin rpy="0 0 0" xyz="0 0 0"/>
      <geometry>
        <mesh filename="file:///home/junglator/pandora_ws/install/gypsy_robot/share/gypsy_robot/meshes/mobile_bot/realsense.obj" scale="0.001 0.001 0.001"/>
      </geometry>
      <material name="light_grey"/>
    </visual>
    <collision>
      <origin rpy="0 0 0" xyz="0 0 0"/>
      <geometry>
        <mesh filename="file:///home/junglator/pandora_ws/install/gypsy_robot/share/gypsy_robot/meshes/mobile_bot/realsense.obj" scale="0.001 0.001 0.001"/>
      </geometry>
      <material name="light_grey"/>
    </collision>
    <inertial>
      <origin rpy="0 0 0" xyz="0 0 0"/>
      <mass value="0.057836"/>
      <inertia ixx="0.0000046258" ixy="0.00" ixz="0.00" iyy="0.000052583276" iyz="0.0" izz="0.000052583276"/>
    </inertial>
  </link>
  <link name="camera_two">
    <visual>
      <origin rpy="0 0 0" xyz="0 0 0"/>
      <geometry>
        <mesh filename="file:///home/junglator/pandora_ws/install/gypsy_robot/share/gypsy_robot/meshes/mobile_bot/realsense.obj" scale="0.001 0.001 0.001"/>
      </geometry>
      <material name="light_grey"/>
    </visual>
    <collision>
      <origin rpy="0 0 0" xyz="0 0 0"/>
      <geometry>
        <mesh filename="file:///home/junglator/pandora_ws/install/gypsy_robot/share/gypsy_robot/meshes/mobile_bot/realsense.obj" scale="0.001 0.001 0.001"/>
      </geometry>
      <material name="light_grey"/>
    </collision>
    <inertial>
      <origin rpy="0 0 0" xyz="0 0 0"/>
      <mass value="0.057836"/>
      <inertia ixx="0.0000046258" ixy="0.00" ixz="0.00" iyy="0.000052583276" iyz="0.0" izz="0.000052583276"/>
    </inertial>
  </link>
  <!--##################### LASER Link ####################-->
  <link name="laser_link">
    <visual>
      <origin rpy="0 0 0" xyz="0 0 0"/>
      <geometry>
        <box size="0.001 0.001 0.001"/>
      </geometry>
    </visual>
  </link>
  <!--##################### IMU Link ####################-->
  <link name="imu_link">
    <inertial>
      <mass value="0.001"/>
      <origin rpy="0 0 0" xyz="0 0 0"/>
      <inertia ixx="1e-09" ixy="0.0" ixz="0.0" iyy="1e-09" iyz="0.0" izz="1e-09"/>
    </inertial>
  </link>
  <!--###################### JOINTS ########################-->
  <joint name="front_left_wheel_joint" type="continuous">
    <origin rpy="0 0 0" xyz="-0.273 0.2237 -0.12"/>
    <parent link="chassis"/>
    <child link="right_front_wheel"/>
    <axis xyz="1 0 0 "/>
  </joint>
  <joint name="rear_left_wheel_joint" type="continuous">
    <origin rpy="0 0 0" xyz="-0.273 -0.2237 -0.12"/>
    <parent link="chassis"/>
    <child link="left_rear_wheel"/>
    <axis xyz="1 0 0"/>
  </joint>
  <joint name="front_right_wheel_joint" type="continuous">
    <origin rpy="0 0 0" xyz="0.273 0.2237 -0.12"/>
    <parent link="chassis"/>
    <child link="left_front_wheel"/>
    <axis xyz="1 0 0"/>
  </joint>
  <joint name="rear_right_wheel_joint" type="continuous">
    <origin rpy="0 0 0" xyz="0.273 -0.2237 -0.12"/>
    <parent link="chassis"/>
    <child link="right_rear_wheel"/>
    <axis xyz="1 0 0"/>
  </joint>
  <joint name="bin_joint_one" type="fixed">
    <origin rpy="1.5707963267948966 0 0" xyz="0.185 -0.15 0.231"/>
    <parent link="chassis"/>
    <child link="bin_red"/>
    <axis xyz="1 0 0"/>
  </joint>
  <joint name="bin_joint_two" type="fixed">
    <origin rpy="1.5707963267948966 0 0" xyz="-0.185 -0.15 0.231"/>
    <parent link="chassis"/>
    <child link="bin_green"/>
    <axis xyz="1 0 0"/>
  </joint>
  <joint name="camera_joint" type="fixed">
    <origin rpy="-1.5707963267948966 0 0" xyz="0.0 0.395 0.074"/>
    <parent link="chassis"/>
    <child link="camera_one"/>
    <axis xyz="1 0 0"/>
  </joint>
  <joint name="imu_joint" type="fixed">
    <parent link="chassis"/>
    <child link="imu_link"/>
    <origin rpy="0 0 0" xyz="0 0 0"/>
  </joint>
  <joint name="laser_link_joint" type="fixed">
    <parent link="camera_one"/>
    <child link="laser_link"/>
    <origin rpy="1.57 -1.57 0" xyz="0 0 0"/>
  </joint>
  <!--Panda Arm transmission-->
  <gazebo reference="panda_joint1">
    <!-- Needed for ODE to output external wrenches on joints -->
    <provideFeedback>true</provideFeedback>
  </gazebo>
  <transmission name="panda_joint1_transmission">
    <type>transmission_interface/SimpleTransmission</type>
    <joint name="panda_joint1">
      <hardwareInterface>hardware_interface/EffortJointInterface</hardwareInterface>
    </joint>
    <actuator name="panda_joint1_motor">
      <hardwareInterface>hardware_interface/EffortJointInterface</hardwareInterface>
      <mechanicalReduction>1</mechanicalReduction>
    </actuator>
  </transmission>
  <gazebo reference="panda_joint2">
    <!-- Needed for ODE to output external wrenches on joints -->
    <provideFeedback>true</provideFeedback>
  </gazebo>
  <transmission name="panda_joint2_transmission">
    <type>transmission_interface/SimpleTransmission</type>
    <joint name="panda_joint2">
      <hardwareInterface>hardware_interface/EffortJointInterface</hardwareInterface>
    </joint>
    <actuator name="panda_joint2_motor">
      <hardwareInterface>hardware_interface/EffortJo  intInterface</hardwareInterface>
      <mechanicalReduction>1</mechanicalReduction>
    </actuator>
  </transmission>
  <gazebo reference="panda_joint3">
    <!-- Needed for ODE to output external wrenches on joints -->
    <provideFeedback>true</provideFeedback>
  </gazebo>
  <transmission name="panda_joint3_transmission">
    <type>transmission_interface/SimpleTransmission</type>
    <joint name="panda_joint3">
      <hardwareInterface>hardware_interface/EffortJointInterface</hardwareInterface>
    </joint>
    <actuator name="panda_joint3_motor">
      <hardwareInterface>hardware_interface/EffortJointInterface</hardwareInterface>
      <mechanicalReduction>1</mechanicalReduction>
    </actuator>
  </transmission>
  <gazebo reference="panda_joint4">
    <!-- Needed for ODE to output external wrenches on joints -->
    <provideFeedback>true</provideFeedback>
  </gazebo>
  <transmission name="panda_joint4_transmission">
    <type>transmission_interface/SimpleTransmission</type>
    <joint name="panda_joint4">
      <hardwareInterface>hardware_interface/EffortJointInterface</hardwareInterface>
    </joint>
    <actuator name="panda_joint4_motor">
      <hardwareInterface>hardware_interface/EffortJointInterface</hardwareInterface>
      <mechanicalReduction>1</mechanicalReduction>
    </actuator>
  </transmission>
  <gazebo reference="panda_joint5">
    <!-- Needed for ODE to output external wrenches on joints -->
    <provideFeedback>true</provideFeedback>
  </gazebo>
  <transmission name="panda_joint5_transmission">
    <type>transmission_interface/SimpleTransmission</type>
    <joint name="panda_joint5">
      <hardwareInterface>hardware_interface/EffortJointInterface</hardwareInterface>
    </joint>
    <actuator name="panda_joint5_motor">
      <hardwareInterface>hardware_interface/EffortJointInterface</hardwareInterface>
      <mechanicalReduction>1</mechanicalReduction>
    </actuator>
  </transmission>
  <gazebo reference="panda_joint6">
    <!-- Needed for ODE to output external wrenches on joints -->
    <provideFeedback>true</provideFeedback>
  </gazebo>
  <transmission name="panda_joint6_transmission">
    <type>transmission_interface/SimpleTransmission</type>
    <joint name="panda_joint6">
      <hardwareInterface>hardware_interface/EffortJointInterface</hardwareInterface>
    </joint>
    <actuator name="panda_joint6_motor">
      <hardwareInterface>hardware_interface/EffortJointInterface</hardwareInterface>
      <mechanicalReduction>1</mechanicalReduction>
    </actuator>
  </transmission>
  <gazebo reference="panda_joint7">
    <!-- Needed for ODE to output external wrenches on joints -->
    <provideFeedback>true</provideFeedback>
  </gazebo>
  <transmission name="panda_joint7_transmission">
    <type>transmission_interface/SimpleTransmission</type>
    <joint name="panda_joint7">
      <hardwareInterface>hardware_interface/EffortJointInterface</hardwareInterface>
    </joint>
    <actuator name="panda_joint7_motor">
      <hardwareInterface>hardware_interface/EffortJointInterface</hardwareInterface>
      <mechanicalReduction>1</mechanicalReduction>
    </actuator>
  </transmission>
  <transmission name="panda_leftfinger_transmission">
    <type>transmission_interface/SimpleTransmission</type>
    <joint name="finger_joint1">
      <hardwareInterface>hardware_interface/EffortJointInterface</hardwareInterface>
    </joint>
    <actuator name="leftfinger_actuator">
      <hardwareInterface>hardware_interface/EffortJointInterface</hardwareInterface>
      <mechanicalReduction>1</mechanicalReduction>
    </actuator>
  </transmission>
  <transmission name="panda_rightfinger_transmission">
    <type>transmission_interface/SimpleTransmission</type>
    <joint name="finger_joint2">
      <hardwareInterface>hardware_interface/EffortJointInterface</hardwareInterface>
    </joint>
    <actuator name="rightfinger_actuator">
      <hardwareInterface>hardware_interface/EffortJointInterface</hardwareInterface>
      <mechanicalReduction>1</mechanicalReduction>
    </actuator>
  </transmission>
  <!--Drive wheel transmission-->
  <transmission name="front_left_wheel_transmission">
    <type>transmission_interface/SimpleTransmission</type>
    <joint name="front_left_wheel_joint">
      <hardwareInterface>hardware_interface/VelocityJointInterface</hardwareInterface>
    </joint>
    <actuator name="FrontLeftWheelActuator">
      <hardwareInterface>hardware_interface/VelocityJointInterface</hardwareInterface>
      <mechanicalReduction>3</mechanicalReduction>
    </actuator>
  </transmission>
  <transmission name="front_right_wheel_transmission">
    <type>transmission_interface/SimpleTransmission</type>
    <joint name="front_right_wheel_joint">
      <hardwareInterface>hardware_interface/VelocityJointInterface</hardwareInterface>
    </joint>
    <actuator name="FrontRightWheelActuator">
      <hardwareInterface>hardware_interface/VelocityJointInterface</hardwareInterface>
      <mechanicalReduction>3</mechanicalReduction>
    </actuator>
  </transmission>
  <transmission name="rear_left_wheel_transmission">
    <type>transmission_interface/SimpleTransmission</type>
    <joint name="rear_left_wheel_joint">
      <hardwareInterface>hardware_interface/VelocityJointInterface</hardwareInterface>
    </joint>
    <actuator name="ReartLeftWheelActuator">
      <hardwareInterface>hardware_interface/VelocityJointInterface</hardwareInterface>
      <mechanicalReduction>3</mechanicalReduction>
    </actuator>
  </transmission>
  <transmission name="rear_right_wheel_transmission">
    <type>transmission_interface/SimpleTransmission</type>
    <joint name="rear_right_wheel_joint">
      <hardwareInterface>hardware_interface/VelocityJointInterface</hardwareInterface>
    </joint>
    <actuator name="RearRightWheelActuator">
      <hardwareInterface>hardware_interface/VelocityJointInterface</hardwareInterface>
      <mechanicalReduction>3</mechanicalReduction>
    </actuator>
  </transmission>
  <!--########################## MOBILE BOT ################################-->
  <gazebo reference="chassis">
    <material>Gazebo/Grey</material>
  </gazebo>
  <gazebo reference="bin_red">
    <material>Gazebo/Red</material>
  </gazebo>
  <gazebo reference="bin_green">
    <material>Gazebo/Green</material>
  </gazebo>
  <gazebo reference="left_front_wheel">
    <material>Gazebo/Black</material>
  </gazebo>
  <gazebo reference="left_rear_wheel">
    <material>Gazebo/Black</material>
  </gazebo>
  <gazebo reference="right_front_wheel">
    <material>Gazebo/Black</material>
  </gazebo>
  <gazebo reference="right_rear_wheel">
    <material>Gazebo/Black</material>
  </gazebo>
  <gazebo reference="camera_one">
    <material>Gazebo/FlatBlack</material>
  </gazebo>
  <gazebo reference="camera_two">
    <material>Gazebo/FlatBlack</material>
  </gazebo>
  <!--################################# PANDA ARM ########################################-->
  <gazebo reference="panda_link0">
    <material>Gazebo/Orange</material>
  </gazebo>
  <gazebo reference="panda_link1">
    <material>Gazebo/Orange</material>
  </gazebo>
  <gazebo reference="panda_link2">
    <material>Gazebo/Orange</material>
  </gazebo>
  <gazebo reference="panda_link3">
    <material>Gazebo/Orange</material>
  </gazebo>
  <gazebo reference="panda_link4">
    <material>Gazebo/Orange</material>
  </gazebo>
  <gazebo reference="panda_link5">
    <material>Gazebo/Orange</material>
  </gazebo>
  <gazebo reference="panda_link6">
    <material>$panda_body_color}</material>
  </gazebo>
  <gazebo reference="panda_link7">
    <material>Gazebo/Orange</material>
  </gazebo>
  <gazebo reference="hand">
    <material>Gazebo/Orange</material>
  </gazebo>
  <gazebo reference="leftfinger">
    <material>Gazebo/Black</material>
  </gazebo>
  <gazebo reference="rightfinger">
    <material>Gazebo/Black</material>
  </gazebo>
  <gazebo reference="chassis">
    <gravity>true</gravity>
  </gazebo>
  <!--IMU PLUGIN-->
  <gazebo reference="imu_link">
    <gravity>true</gravity>
    <sensor name="imu_sensor" type="imu">
      <always_on>true</always_on>
      <plugin filename="libgazebo_ros_imu_sensor.so" name="imu_plugin">
        <updateRate>30.0</updateRate>
        <bodyName>imu_link</bodyName>
        <topicName>imu/data</topicName>
        <frameName>imu_link</frameName>
        <!--gaussianNoise>0.001</gaussianNoise-->
        <xyzOffset>0 0 0</xyzOffset>
        <rpyOffset>0 0 0</rpyOffset>
        <initialOrientationAsReference>false</initialOrientationAsReference>
      </plugin>
      <pose>0 0 0 0 0 0</pose>
    </sensor>
  </gazebo>
  <!--CAMERA PLUGIN-->
  <gazebo reference="camera_one">
    <sensor name="camera_one_rgb_camera" type="camera">
      <update_rate>10.0</update_rate>
      <camera name="cam_one_rgb_camera">
        <pose>0 0 0 0 -1.57 1.57</pose>
        <horizontal_fov>1.3962634</horizontal_fov>
        <image>
          <width>640</width>
          <height>480</height>
          <format>R8G8B8</format>
        </image>
        <clip>
          <near>0.005</near>
          <far>10.0</far>
        </clip>
      </camera>
      <plugin filename="libgazebo_ros_camera.so" name="camera_one_controller">
        <alwaysOn>true</alwaysOn>
        <updateRate>0.0</updateRate>
        <cameraName>rgb_camera</cameraName>
        <imageTopicName>image_raw</imageTopicName>
        <cameraInfoTopicName>camera_info</cameraInfoTopicName>
        <frameName>cam_one_rgb_cam_camera_link_frame</frameName>
        <hackBaseline>0.07</hackBaseline>
        <distortionK1>0.0</distortionK1>
        <distortionK2>0.0</distortionK2>
        <distortionK3>0.0</distortionK3>
        <distortionT1>0.0</distortionT1>
        <distortionT2>0.0</distortionT2>
      </plugin>
    </sensor>
  </gazebo>
  <gazebo reference="camera_two">
    <sensor name="camera_two_rgb_camera" type="camera">
      <update_rate>10.0</update_rate>
      <camera name="camera_two_rgb_camera">
        <pose>0 0 0 0 -1.57 1.57</pose>
        <horizontal_fov>1.3962634</horizontal_fov>
        <image>
          <width>640</width>
          <height>480</height>
          <format>R8G8B8</format>
        </image>
        <clip>
          <near>0.005</near>
          <far>10.0</far>
        </clip>
      </camera>
      <plugin filename="libgazebo_ros_camera.so" name="camera_two_controller">
        <alwaysOn>true</alwaysOn>
        <updateRate>0.0</updateRate>
        <cameraName>rgb_camera</cameraName>
        <imageTopicName>image_raw</imageTopicName>
        <cameraInfoTopicName>camera_info</cameraInfoTopicName>
        <frameName>cam_one_rgb_cam_camera_link_frame</frameName>
        <hackBaseline>0.07</hackBaseline>
        <distortionK1>0.0</distortionK1>
        <distortionK2>0.0</distortionK2>
        <distortionK3>0.0</distortionK3>
        <distortionT1>0.0</distortionT1>
        <distortionT2>0.0</distortionT2>
      </plugin>
    </sensor>
  </gazebo>
  <!--LASER PLUGIN-->
  <gazebo reference="laser_link">
    <sensor name="laser_scanner" type="ray">
      <pose>0 0 0 0 0 0</pose>
      <ray>
        <scan>
          <horizontal>
            <samples>181</samples>
            <resolution>1</resolution>
            <min_angle>-1.57080</min_angle>
            <max_angle>1.57080</max_angle>
          </horizontal>
        </scan>
        <range>
          <min>0.08</min>
          <max>10</max>
          <resolution>0.05</resolution>
        </range>
        <noise>
          <type>gaussian</type>
          <mean>0.0</mean>
          <stddev>0.01</stddev>
        </noise>
      </ray>
      <always_on>1</always_on>
      <update_rate>30</update_rate>
      <visualize>true</visualize>
      <plugin filename="libgazebo_ros_ray_sensor.so" name="laser_scanner">
        <ros>
          <namespace>/</namespace>
          <argument>~/out:=laser</argument>
        </ros>
        <output_type>sensor_msgs/PointCloud2</output_type>
        <frame_name>laser_link</frame_name>
      </plugin>
    </sensor>
  </gazebo>
  <!--MECANUM WHEEL PLUGIN-->
  <!--gazebo>
    <!instead of using plugins for every wheel; used planar plugin to move the mobile bot>
        <plugin name="mecanum_controller" filename="libgazebo_ros_planar_move.so"> 
            <commandTopic>cmd_vel</commandTopic>
            <odometryTopic>odom</odometryTopic>
            <odometryFrame>odom</odometryFrame>
            <odometryRate>100.0</odometryRate>
            <update_rate>100</update_rate>
            <publish_rate>10</publish_rate>
            <robotBaseFrame>base_footprint</robotBaseFrame> 
            <publishTF>false</publishTF>
            <covariance_x>0.0001</covariance_x>
			      <covariance_y>0.0001</covariance_y>
			      <covariance_yaw>0.01</covariance_yaw>
        </plugin>
    </gazebo-->
  <gazebo>
    <plugin filename="libgazebo_ros_diff_drive.so" name="wheel_drive_controller">
      <!-- wheels -->
      <num_wheel_pairs>2</num_wheel_pairs>
      <left_joint>front_left_wheel_joint</left_joint>
      <left_joint>rear_left_wheel_joint</left_joint>
      <right_joint>front_right_wheel_joint</right_joint>
      <right_joint>rear_right_wheel_joint</right_joint>
      <!-- kinematics -->
      <wheel_separation>0.3</wheel_separation>
      <wheel_diameter>0.06</wheel_diameter>
      <max_wheel_torque>20.0</max_wheel_torque>
      <max_wheel_acceleration>10.0</max_wheel_acceleration>
      <!-- odometry  -->
      <odometry_source>world</odometry_source>
      <odometry_frame>odom</odometry_frame>
      <robot_base_frame>base_footprint</robot_base_frame>
      <!-- topic & re remappings -->
      <ros>
        <namespace>/</namespace>
        <argument>/cmd_vel:=cmd_vel</argument>
        <argument>/odom:=odom</argument>
      </ros>
      <publish_odom>true</publish_odom>
      <publish_odom_tf>true</publish_odom_tf>
      <update_rate>100.0</update_rate>
    </plugin>
  </gazebo>
  <gazebo reference="front_left_wheel">
    <mu1 value="1.0"/>
    <mu2 value="1.0"/>
    <kp value="10000000.0"/>
    <kd value="1.0"/>
    <fdir1 value="1 0 0"/>
  </gazebo>
  <gazebo reference="front_right_wheel">
    <mu1 value="1.0"/>
    <mu2 value="1.0"/>
    <kp value="10000000.0"/>
    <kd value="1.0"/>
    <fdir1 value="1 0 0"/>
  </gazebo>
  <gazebo reference="rear_left_wheel">
    <mu1 value="1.0"/>
    <mu2 value="1.0"/>
    <kp value="10000000.0"/>
    <kd value="1.0"/>
    <fdir1 value="1 0 0"/>
  </gazebo>
  <gazebo reference="rear_right_wheel">
    <mu1 value="1.0"/>
    <mu2 value="1.0"/>
    <kp value="10000000.0"/>
    <kd value="1.0"/>
    <fdir1 value="1 0 0"/>
  </gazebo>
  <gazebo reference="panda_link0">
    <mu1>0.2</mu1>
    <mu2>0.2</mu2>
    <gravity>true</gravity>
    <self_collide>true</self_collide>
  </gazebo>
  <gazebo reference="panda_link1">
    <mu1>0.2</mu1>
    <mu2>0.2</mu2>
    <gravity>true</gravity>
    <self_collide>true</self_collide>
  </gazebo>
  <gazebo reference="panda_link2">
    <mu1>0.2</mu1>
    <mu2>0.2</mu2>
    <gravity>true</gravity>
    <self_collide>true</self_collide>
  </gazebo>
  <gazebo reference="panda_link3">
    <mu1>0.2</mu1>
    <mu2>0.2</mu2>
    <gravity>true</gravity>
    <self_collide>true</self_collide>
  </gazebo>
  <gazebo reference="panda_link4">
    <mu1>0.2</mu1>
    <mu2>0.2</mu2>
    <gravity>true</gravity>
    <self_collide>true</self_collide>
  </gazebo>
  <gazebo reference="panda_link5">
    <mu1>0.2</mu1>
    <mu2>0.2</mu2>
    <gravity>true</gravity>
    <self_collide>true</self_collide>
  </gazebo>
  <gazebo reference="panda_link6">
    <mu1>0.2</mu1>
    <mu2>0.2</mu2>
    <gravity>true</gravity>
    <self_collide>true</self_collide>
  </gazebo>
  <gazebo reference="panda_link7">
    <mu1>0.2</mu1>
    <mu2>0.2</mu2>
    <gravity>true</gravity>
    <self_collide>true</self_collide>
  </gazebo>
  <gazebo reference="panda_link8">
    <gravity>true</gravity>
    <self_collide>true</self_collide>
  </gazebo>
  <gazebo reference="hand">
    <mu1>0.85</mu1>
    <mu2>0.85</mu2>
    <gravity>true</gravity>
    <self_collide>true</self_collide>
  </gazebo>
  <gazebo reference="leftfinger">
    <kp>1000000.0</kp>
    <kd>1.0</kd>
    <mu1>1.13</mu1>
    <mu2>1.13</mu2>
    <gravity>true</gravity>
    <self_collide>true</self_collide>
  </gazebo>
  <gazebo reference="rightfinger">
    <kp>1000000.0</kp>
    <kd>1.0</kd>
    <mu1>1.13</mu1>
    <mu2>1.13</mu2>
    <gravity>true</gravity>
    <self_collide>true</self_collide>
  </gazebo>
  <!--Properties-->
  <!--Panda Arm control-->
  <ros2_control name="panda_arm_system" type="system">
    <hardware>
      <plugin>gazebo_ros2_control/GazeboSystem</plugin>
    </hardware>
    <joint name="panda_joint1">
      <param name="initial_position">0.0</param>
      <command_interface name="effort"/>
      <state_interface name="velocity"/>
      <state_interface name="position"/>
      <state_interface name="effort"/>
    </joint>
    <joint name="panda_joint2">
      <param name="initial_position">-0.7853981633974483</param>
      <command_interface name="effort"/>
      <state_interface name="velocity"/>
      <state_interface name="position"/>
      <state_interface name="effort"/>
    </joint>
    <joint name="panda_joint3">
      <param name="initial_position">0.0</param>
      <command_interface name="effort"/>
      <state_interface name="velocity"/>
      <state_interface name="position"/>
      <state_interface name="effort"/>
    </joint>
    <joint name="panda_joint4">
      <param name="initial_position">-2.356194490192345</param>
      <command_interface name="effort"/>
      <state_interface name="velocity"/>
      <state_interface name="position"/>
      <state_interface name="effort"/>
    </joint>
    <joint name="panda_joint5">
      <param name="initial_position">0.0</param>
      <command_interface name="effort"/>
      <state_interface name="velocity"/>
      <state_interface name="position"/>
      <state_interface name="effort"/>
    </joint>
    <joint name="panda_joint6">
      <param name="initial_position">1.5707963267948966</param>
      <command_interface name="effort"/>
      <state_interface name="velocity"/>
      <state_interface name="position"/>
      <state_interface name="effort"/>
    </joint>
    <joint name="panda_joint7">
      <param name="initial_position">0.7853981633974483</param>
      <command_interface name="effort"/>
      <state_interface name="velocity"/>
      <state_interface name="position"/>
      <state_interface name="effort"/>
    </joint>
  </ros2_control>
  <!--Gripper control-->
  <ros2_control name="panda_gripper_system" type="system">
    <hardware>
      <plugin>gazebo_ros2_control/GazeboSystem</plugin>
    </hardware>
    <joint name="finger_joint1">
      <param name="initial_position">0.0</param>
      <command_interface name="effort"/>
      <state_interface name="position"/>
      <state_interface name="velocity"/>
      <state_interface name="effort"/>
    </joint>
    <joint name="finger_joint2">
      <param name="initial_position">0.0</param>
      <command_interface name="effort"/>
      <state_interface name="position"/>
      <state_interface name="velocity"/>
      <state_interface name="effort"/>
    </joint>
  </ros2_control>
  <!--Mobile bot control-->
  <ros2_control name="mobile_bot_system" type="system">
    <hardware>
      <plugin>gazebo_ros2_control/GazeboSystem</plugin>
    </hardware>
    <joint name="front_left_wheel_joint">
      <command_interface name="velocity">
        <param name="min">-10</param>
        <param name="max">10</param>
      </command_interface>
      <state_interface name="velocity"/>
      <state_interface name="position"/>
    </joint>
    <joint name="front_right_wheel_joint">
      <command_interface name="velocity">
        <param name="min">-10</param>
        <param name="max">10</param>
      </command_interface>
      <state_interface name="velocity"/>
      <state_interface name="position"/>
    </joint>
    <joint name="rear_left_wheel_joint">
      <command_interface name="velocity">
        <param name="min">-10</param>
        <param name="max">10</param>
      </command_interface>
      <state_interface name="velocity"/>
      <state_interface name="position"/>
    </joint>
    <joint name="rear_right_wheel_joint">
      <command_interface name="velocity">
        <param name="min">-10</param>
        <param name="max">10</param>
      </command_interface>
      <state_interface name="velocity"/>
      <state_interface name="position"/>
    </joint>
  </ros2_control>
  <!--Pulgin setup-->
  <gazebo>
    <plugin filename="libgazebo_ros2_control.so" name="gazebo_ros2_control">
      <parameters>/home/junglator/pandora_ws/install/gypsy_robot/share/gypsy_robot/config/panda_controller.yaml</parameters>
    </plugin>
  </gazebo>
  <gazebo>
    <plugin filename="libgazebo_ros2_control.so" name="gazebo_ros2_control">
      <parameters>/home/junglator/pandora_ws/install/gypsy_robot/share/gypsy_robot/config/mobile_bot_controller.yaml</parameters>
    </plugin>
  </gazebo>
  <!--########################################################################################-->
  <link name="base_footprint"/>
  <joint name="base_link_joint" type="fixed">
    <origin rpy="0 0 1.5707963267948966" xyz="0 0 0.15"/>
    <parent link="base_footprint"/>
    <child link="chassis"/>
    <axis xyz="0 0 0"/>
  </joint>
  <joint name="arm_joint" type="fixed">
    <origin rpy="0 0 1.5707963267948966" xyz="0 0.3 0.1325"/>
    <parent link="chassis"/>
    <child link="panda_link0"/>
  </joint>
  <joint name="arm_camera_joint" type="fixed">
    <origin rpy="0 0 0.7853981633974483" xyz="0.04 -0.032 0.03"/>
    <parent link="panda_link8"/>
    <child link="camera_two"/>
    <axis xyz="1 0 0"/>
  </joint>
</robot>
