<?xml version="1.0" ?>
<!-- =================================================================================== -->
<!-- |    This document was autogenerated by xacro from gypsy.urdf.xacro               | -->
<!-- |    EDITING THIS FILE BY HAND IS NOT RECOMMENDED                                 | -->
<!-- =================================================================================== -->
<robot name="gypsy">
  <link name="panda_link0">
    <visual>
      <origin rpy="0 0 0" xyz="0 0 0"/>
      <geometry>
        <mesh filename="file:///home/junglator/pandora_ws/install/gypsy_robot/share/gypsy_robot/meshes/panda_arm/link0.obj"/>
      </geometry>
    </visual>
    <collision>
      <origin rpy="0 0 0" xyz="0 0 0"/>
      <geometry>
        <mesh filename="file:///home/junglator/pandora_ws/install/gypsy_robot/share/gypsy_robot/meshes/panda_arm/link0.obj"/>
      </geometry>
    </collision>
    <inertial>
      <origin rpy="0 0 0" xyz="-0.041018 -0.00014 0.049974"/>
      <mass value="0.629769"/>
      <inertia ixx="0.00315" ixy="8.2904E-07" ixz="0.00015" iyy="0.00388" iyz="8.2299E-06" izz="0.004285"/>
    </inertial>
  </link>
  <link name="panda_link1">
    <visual>
      <origin rpy="0 0 0" xyz="0 0 0"/>
      <geometry>
        <mesh filename="file:///home/junglator/pandora_ws/install/gypsy_robot/share/gypsy_robot/meshes/panda_arm/link1.obj"/>
      </geometry>
    </visual>
    <collision>
      <origin rpy="0 0 0" xyz="0 0 0"/>
      <geometry>
        <mesh filename="file:///home/junglator/pandora_ws/install/gypsy_robot/share/gypsy_robot/meshes/panda_arm/link1.obj"/>
      </geometry>
    </collision>
    <inertial>
      <origin rpy="0 0 0" xyz="0.0082121602797146209 -0.026532335711888823 -0.047138121275696603"/>
      <mass value="4.9706751871147938"/>
      <inertia ixx="0.70141461794089599" ixy="-0.00063981642154032682" ixz="0.0078364148804466946" iyy="0.70480134490761892" iyz="0.01074540620106503" izz="0.010111109106129931"/>
    </inertial>
  </link>
  <link name="panda_link2">
    <visual>
      <origin rpy="0 0 0" xyz="0 0 0"/>
      <geometry>
        <mesh filename="file:///home/junglator/pandora_ws/install/gypsy_robot/share/gypsy_robot/meshes/panda_arm/link2.obj"/>
      </geometry>
    </visual>
    <collision>
      <origin rpy="0 0 0" xyz="0 0 0"/>
      <geometry>
        <mesh filename="file:///home/junglator/pandora_ws/install/gypsy_robot/share/gypsy_robot/meshes/panda_arm/link2.obj"/>
      </geometry>
    </collision>
    <inertial>
      <origin rpy="0 0 0" xyz="-0.0088444802449167883 -0.027531520310653038 -0.00055850347148591131"/>
      <mass value="0.64712411452542207"/>
      <inertia ixx="0.012028228395010528" ixy="-0.005176957021186453" ixz="0.028416723889140006" iyy="0.034001000715476563" iyz="-0.0034872992153212263" izz="0.026005490424668338"/>
    </inertial>
  </link>
  <link name="panda_link3">
    <visual>
      <origin rpy="0 0 0" xyz="0 0 0"/>
      <geometry>
        <mesh filename="file:///home/junglator/pandora_ws/install/gypsy_robot/share/gypsy_robot/meshes/panda_arm/link3.obj"/>
      </geometry>
    </visual>
    <collision>
      <origin rpy="0 0 0" xyz="0 0 0"/>
      <geometry>
        <mesh filename="file:///home/junglator/pandora_ws/install/gypsy_robot/share/gypsy_robot/meshes/panda_arm/link3.obj"/>
      </geometry>
    </collision>
    <inertial>
      <origin rpy="0 0 0" xyz="0.028340188017725303 0.037617533422114727 -0.067208806995820797"/>
      <mass value="3.2283417206016849"/>
      <inertia ixx="0.035865608781665073" ixy="-0.0048981742215283711" ixz="-0.01683647440270046" iyy="0.041062395573147469" iyz="-0.012957871374295925" izz="0.0072954180594979098"/>
    </inertial>
  </link>
  <link name="panda_link4">
    <visual>
      <origin rpy="0 0 0" xyz="0 0 0"/>
      <geometry>
        <mesh filename="file:///home/junglator/pandora_ws/install/gypsy_robot/share/gypsy_robot/meshes/panda_arm/link4.obj"/>
      </geometry>
    </visual>
    <collision>
      <origin rpy="0 0 0" xyz="0 0 0"/>
      <geometry>
        <mesh filename="file:///home/junglator/pandora_ws/install/gypsy_robot/share/gypsy_robot/meshes/panda_arm/link4.obj"/>
      </geometry>
    </collision>
    <inertial>
      <origin rpy="0 0 0" xyz="-0.052863658713578371 0.10286796966271235 0.027230575794129856"/>
      <mass value="3.5877058164189872"/>
      <inertia ixx="0.023713305935381724" ixy="0.019494904018681623" ixz="-0.00041806758858047981" iyy="0.016777579582937466" iyz="0.0073688153189040975" izz="0.03323445513208665"/>
    </inertial>
  </link>
  <link name="panda_link5">
    <visual>
      <origin rpy="0 0 0" xyz="0 0 0"/>
      <geometry>
        <mesh filename="file:///home/junglator/pandora_ws/install/gypsy_robot/share/gypsy_robot/meshes/panda_arm/link5.obj"/>
      </geometry>
    </visual>
    <collision>
      <origin rpy="0 0 0" xyz="0 0 0"/>
      <geometry>
        <mesh filename="file:///home/junglator/pandora_ws/install/gypsy_robot/share/gypsy_robot/meshes/panda_arm/link5.obj"/>
      </geometry>
    </collision>
    <inertial>
      <origin rpy="0 0 0" xyz="-0.0081910657546574537 0.042932437976240877 -0.03621309770351528"/>
      <mass value="1.2258764841419181"/>
      <inertia ixx="0.039833353765046244" ixy="-0.0041636653470603583" ixz="-0.0057791872240629304" iyy="0.027963868212344253" iyz="0.0057981330723796617" izz="0.0058527143406942126"/>
    </inertial>
  </link>
  <link name="panda_link6">
    <visual>
      <origin rpy="0 0 0" xyz="0 0 0"/>
      <geometry>
        <mesh filename="file:///home/junglator/pandora_ws/install/gypsy_robot/share/gypsy_robot/meshes/panda_arm/link6.obj"/>
      </geometry>
    </visual>
    <collision>
      <origin rpy="0 0 0" xyz="0 0 0"/>
      <geometry>
        <mesh filename="file:///home/junglator/pandora_ws/install/gypsy_robot/share/gypsy_robot/meshes/panda_arm/link6.obj"/>
      </geometry>
    </collision>
    <inertial>
      <origin rpy="0 0 0" xyz="0.060550072294159214 -0.013508438365027796 -0.014648696562393272"/>
      <mass value="1.6660195957719575"/>
      <inertia ixx="0.0018946535529745841" ixy="3.0085693236067733e-05" ixz="-0.0014917301754574759" iyy="0.0059333708668997337" iyz="0.001150006504840946" izz="0.0039230158812056833"/>
    </inertial>
  </link>
  <link name="panda_link7">
    <visual>
      <origin rpy="0 0 0" xyz="0 0 0"/>
      <geometry>
        <mesh filename="file:///home/junglator/pandora_ws/install/gypsy_robot/share/gypsy_robot/meshes/panda_arm/link7.obj"/>
      </geometry>
    </visual>
    <collision>
      <origin rpy="0 0 0" xyz="0 0 0"/>
      <geometry>
        <mesh filename="file:///home/junglator/pandora_ws/install/gypsy_robot/share/gypsy_robot/meshes/panda_arm/link7.obj"/>
      </geometry>
    </collision>
    <inertial>
      <origin rpy="0 0 0" xyz="0.0084850731223620312 -0.00063346827849231481 0.061428526086978817"/>
      <mass value="0.73598318978014388"/>
      <inertia ixx="0.0096273165930081117" ixy="0.0011836273982315374" ixz="0.0021412918431209403" iyy="0.011335955410605407" iyz="-0.000625294249958001" izz="0.0063944769299665851"/>
    </inertial>
  </link>
  <link name="panda_link8"/>
  <link name="hand">
    <inertial>
      <mass value="0.73"/>
      <origin rpy="0 0 0" xyz="0 0.0015244 0.0275912"/>
      <inertia ixx="0.00278560230025" ixy="0.0" ixz="0.0" iyy="0.000400033405336" iyz="0.0" izz="0.00256378041832"/>
    </inertial>
    <visual>
      <origin rpy="0 0 0" xyz="0 0 0"/>
      <geometry>
        <mesh filename="file:///home/junglator/pandora_ws/install/gypsy_robot/share/gypsy_robot/meshes/panda_arm/hand.obj"/>
      </geometry>
      <material name="">
        <color rgba="1 1 1 1"/>
      </material>
    </visual>
    <collision>
      <origin rpy="0 0 0" xyz="0 0 0"/>
      <geometry>
        <mesh filename="file:///home/junglator/pandora_ws/install/gypsy_robot/share/gypsy_robot/meshes/panda_arm/hand.obj"/>
      </geometry>
    </collision>
  </link>
  <link name="leftfinger">
    <inertial>
      <mass value="0.1"/>
      <origin rpy="0 0 0" xyz="0 0.0145644 0.0227941"/>
      <inertia ixx="3.01220925051e-05" ixy="0.0" ixz="0.0" iyy="2.95873808038e-05" iyz="0.0" izz="6.95125211657e-06"/>
    </inertial>
    <visual>
      <origin rpy="0 0 0" xyz="0 0 0"/>
      <geometry>
        <mesh filename="file:///home/junglator/pandora_ws/install/gypsy_robot/share/gypsy_robot/meshes/panda_arm/finger.obj"/>
      </geometry>
      <material name="">
        <color rgba="1 1 1 1"/>
      </material>
    </visual>
    <collision>
      <origin rpy="0 0 0" xyz="0 0 0"/>
      <geometry>
        <mesh filename="file:///home/junglator/pandora_ws/install/gypsy_robot/share/gypsy_robot/meshes/panda_arm/finger.obj"/>
      </geometry>
    </collision>
  </link>
  <link name="rightfinger">
    <inertial>
      <mass value="0.1"/>
      <origin rpy="0 0 3.1415926535897931" xyz="0 0.0145644 0.0227941"/>
      <inertia ixx="3.01220925051e-05" ixy="0.0" ixz="0.0" iyy="2.95873808038e-05" iyz="0.0" izz="6.95125211657e-06"/>
    </inertial>
    <visual>
      <origin rpy="0 0 3.1415926535897931" xyz="0 0 0"/>
      <geometry>
        <mesh filename="file:///home/junglator/pandora_ws/install/gypsy_robot/share/gypsy_robot/meshes/panda_arm/finger.obj"/>
      </geometry>
      <material name="">
        <color rgba="1 1 1 1"/>
      </material>
    </visual>
    <collision>
      <origin rpy="0 0 3.1415926535897931" xyz="0 0 0"/>
      <geometry>
        <mesh filename="file:///home/junglator/pandora_ws/install/gypsy_robot/share/gypsy_robot/meshes/panda_arm/finger.obj"/>
      </geometry>
    </collision>
  </link>
  <!--###################### JOINTS ########################-->
  <joint name="panda_joint1" type="revolute">
    <safety_controller k_position="100.0" k_velocity="40.0" soft_lower_limit="-2.8973" soft_upper_limit="2.8973"/>
    <origin rpy="0 0 0" xyz="0 0 0.333"/>
    <parent link="panda_link0"/>
    <child link="panda_link1"/>
    <axis xyz="0 0 1"/>
    <limit acceleration="15" effort="87" lower="-2.9671" upper="2.9671" velocity="2.5"/>
    <dynamics D="1" K="7000" damping="0.003" friction="0.0" mu_coulomb="0" mu_viscous="16"/>
  </joint>
  <joint name="panda_joint2" type="revolute">
    <safety_controller k_position="100.0" k_velocity="40.0" soft_lower_limit="-1.7628" soft_upper_limit="1.7628"/>
    <origin rpy="-1.5707963267948966 0 0" xyz="0 0 0"/>
    <parent link="panda_link1"/>
    <child link="panda_link2"/>
    <axis xyz="0 0 1"/>
    <limit acceleration="7.5" effort="87" lower="-1.8326" upper="1.8326" velocity="2.5"/>
    <dynamics D="1" K="7000" damping="0.003" friction="0.0" mu_coulomb="0" mu_viscous="16"/>
  </joint>
  <joint name="panda_joint3" type="revolute">
    <safety_controller k_position="100.0" k_velocity="40.0" soft_lower_limit="-2.8973" soft_upper_limit="2.8973"/>
    <origin rpy="1.5707963267948966 0 0" xyz="0 -0.316 0"/>
    <parent link="panda_link2"/>
    <child link="panda_link3"/>
    <axis xyz="0 0 1"/>
    <limit acceleration="12.5" effort="87" lower="-2.9671" upper="2.9671" velocity="2.5"/>
    <dynamics D="1" K="7000" damping="0.003" friction="0.0" mu_coulomb="0" mu_viscous="16"/>
  </joint>
  <joint name="panda_joint4" type="revolute">
    <safety_controller k_position="100.0" k_velocity="40.0" soft_lower_limit="-3.0718" soft_upper_limit="-0.0698"/>
    <origin rpy="1.5707963267948966 0 0" xyz="0.0825 0 0"/>
    <parent link="panda_link3"/>
    <child link="panda_link4"/>
    <axis xyz="0 0 1"/>
    <limit acceleration="12.5" effort="87" lower="-3.1416" upper="-0.4" velocity="2.5"/>
    <dynamics D="1" K="7000" damping="0.003" friction="0.0" mu_coulomb="0" mu_viscous="16"/>
  </joint>
  <joint name="panda_joint5" type="revolute">
    <safety_controller k_position="100.0" k_velocity="40.0" soft_lower_limit="-2.8973" soft_upper_limit="2.8973"/>
    <origin rpy="-1.5707963267948966 0 0" xyz="-0.0825 0.384 0"/>
    <parent link="panda_link4"/>
    <child link="panda_link5"/>
    <axis xyz="0 0 1"/>
    <limit acceleration="15" effort="12" lower="-2.9671" upper="2.9671" velocity="3"/>
    <dynamics D="1" K="7000" damping="0.003" friction="0.0" mu_coulomb="0" mu_viscous="16"/>
  </joint>
  <joint name="panda_joint6" type="revolute">
    <safety_controller k_position="100.0" k_velocity="40.0" soft_lower_limit="-0.0175" soft_upper_limit="3.7525"/>
    <origin rpy="1.5707963267948966 0 0" xyz="0 0 0"/>
    <parent link="panda_link5"/>
    <child link="panda_link6"/>
    <axis xyz="0 0 1"/>
    <limit acceleration="20" effort="12" lower="-0.0873" upper="3.8223" velocity="3"/>
    <dynamics D="1" K="7000" damping="0.003" friction="0.0" mu_coulomb="0" mu_viscous="16"/>
  </joint>
  <joint name="panda_joint7" type="revolute">
    <safety_controller k_position="100.0" k_velocity="40.0" soft_lower_limit="-2.8973" soft_upper_limit="2.8973"/>
    <origin rpy="1.5707963267948966 0 0" xyz="0.088 0 0"/>
    <parent link="panda_link6"/>
    <child link="panda_link7"/>
    <axis xyz="0 0 1"/>
    <limit acceleration="20" effort="12" lower="-2.9671" upper="2.9671" velocity="3"/>
    <dynamics D="1" K="7000" damping="0.003" friction="0.0" mu_coulomb="0" mu_viscous="16"/>
  </joint>
  <joint name="panda_joint8" type="fixed">
    <origin rpy="0 0 0" xyz="0 0 0.107"/>
    <parent link="panda_link7"/>
    <child link="panda_link8"/>
    <axis xyz="0 0 0"/>
  </joint>
  <joint name="panda_hand_joint" type="fixed">
    <parent link="panda_link8"/>
    <child link="hand"/>
    <origin rpy="0 0 -0.785398163397" xyz="0 0 -0.05"/>
  </joint>
  <joint name="finger_joint1" type="prismatic">
    <parent link="hand"/>
    <child link="leftfinger"/>
    <origin rpy="0 0 0" xyz="0 0 0.0584"/>
    <axis xyz="0 1 0"/>
    <limit effort="20" lower="-0.001" upper="0.04" velocity="0.3"/>
  </joint>
  <joint name="finger_joint2" type="prismatic">
    <parent link="hand"/>
    <child link="rightfinger"/>
    <origin rpy="0 0 0" xyz="0 0 0.0584"/>
    <axis xyz="0 -1 0"/>
    <limit effort="20" lower="-0.001" upper="0.04" velocity="0.3"/>
  </joint>
  <material name="panda_white">
    <color rgba="1. 1. 1. 1."/>
  </material>
  <material name="dark_grey">
    <color rgba="0.2 0.2 0.2 1.0"/>
  </material>
  <material name="light_grey">
    <color rgba="0.4 0.4 0.4 1.0"/>
  </material>
  <material name="red">
    <color rgba="0.8 0.0 0.0 1.0"/>
  </material>
  <material name="white">
    <color rgba="0.9 0.9 0.9 1.0"/>
  </material>
  <material name="black">
    <color rgba="0.15 0.15 0.15 1.0"/>
  </material>
  <link name="chassis">
    <visual>
      <origin rpy="0 0 0" xyz="0 0 0"/>
      <geometry>
        <mesh filename="file:///home/junglator/pandora_ws/install/gypsy_robot/share/gypsy_robot/meshes/mobile_bot/chassis_o.obj"/>
      </geometry>
      <material name="dark_grey"/>
    </visual>
    <collision>
      <origin xyz="0 0 0"/>
      <geometry>
        <mesh filename="file:///home/junglator/pandora_ws/install/gypsy_robot/share/gypsy_robot/meshes/mobile_bot/chassis_o.obj"/>
      </geometry>
      <material name="dark_grey"/>
    </collision>
    <inertial>
      <origin rpy="0 0 0" xyz="0 0 0"/>
      <mass value="30.00"/>
      <!--calcuated on the basis of dimension-->
      <inertia ixx="1.7755" ixy="0.00" ixz="0.00" iyy="1.400" iyz="0.00" izz="2.825"/>
    </inertial>
  </link>
  <link name="left_upper_wheel">
    <visual>
      <origin rpy="0 0 0" xyz="0 0 0"/>
      <geometry>
        <mesh filename="file:///home/junglator/pandora_ws/install/gypsy_robot/share/gypsy_robot/meshes/mobile_bot/Wheel_Left.obj" scale="0.1 0.1 0.1"/>
      </geometry>
      <material name="black"/>
    </visual>
    <collision>
      <origin rpy="0 0 0" xyz="0 0 0"/>
      <geometry>
        <mesh filename="file:///home/junglator/pandora_ws/install/gypsy_robot/share/gypsy_robot/meshes/mobile_bot/Wheel_Left.obj" scale="0.1 0.1 0.1"/>
      </geometry>
      <material name="black"/>
    </collision>
    <inertial>
      <origin rpy="0 0 0" xyz="0 0 0"/>
      <mass value="0.329"/>
      <inertia ixx="0.0000129" ixy="0.00" ixz="0.00" iyy="0.000086529" iyz="0.0" izz="0.000086529"/>
    </inertial>
  </link>
  <link name="left_bottom_wheel">
    <visual>
      <origin rpy="0 0 0" xyz="0 0 0"/>
      <geometry>
        <mesh filename="file:///home/junglator/pandora_ws/install/gypsy_robot/share/gypsy_robot/meshes/mobile_bot/Wheel_Left.obj" scale="0.1 0.1 0.1"/>
      </geometry>
      <material name="black"/>
    </visual>
    <collision>
      <origin rpy="0 0 0" xyz="0 0 0"/>
      <geometry>
        <mesh filename="file:///home/junglator/pandora_ws/install/gypsy_robot/share/gypsy_robot/meshes/mobile_bot/Wheel_Left.obj" scale="0.1 0.1 0.1"/>
      </geometry>
      <material name="black"/>
    </collision>
    <inertial>
      <origin rpy="0 0 0" xyz="0 0 0"/>
      <mass value="0.329"/>
      <inertia ixx="0.0000129" ixy="0.00" ixz="0.00" iyy="0.000086529" iyz="0.0" izz="0.000086529"/>
    </inertial>
  </link>
  <link name="right_upper_wheel">
    <visual>
      <origin rpy="0 0 0" xyz="0 0 0"/>
      <geometry>
        <mesh filename="file:///home/junglator/pandora_ws/install/gypsy_robot/share/gypsy_robot/meshes/mobile_bot/Wheel_Right.obj" scale="0.1 0.1 0.1"/>
      </geometry>
      <material name="black"/>
    </visual>
    <collision>
      <origin rpy="0 0 0" xyz="0 0 0"/>
      <geometry>
        <mesh filename="file:///home/junglator/pandora_ws/install/gypsy_robot/share/gypsy_robot/meshes/mobile_bot/Wheel_Right.obj" scale="0.1 0.1 0.1"/>
      </geometry>
      <material name="black"/>
    </collision>
    <inertial>
      <origin rpy="0 0 0" xyz="0 0 0"/>
      <mass value="0.329"/>
      <inertia ixx="0.0000129" ixy="0.00" ixz="0.00" iyy="0.000086529" iyz="0.0" izz="0.000086529"/>
    </inertial>
  </link>
  <link name="right_bottom_wheel">
    <visual>
      <origin rpy="0 0 0" xyz="0 0 0"/>
      <geometry>
        <mesh filename="file:///home/junglator/pandora_ws/install/gypsy_robot/share/gypsy_robot/meshes/mobile_bot/Wheel_Right.obj" scale="0.1 0.1 0.1"/>
      </geometry>
      <material name="black"/>
    </visual>
    <collision>
      <origin rpy="0 0 0" xyz="0 0 0"/>
      <geometry>
        <mesh filename="file:///home/junglator/pandora_ws/install/gypsy_robot/share/gypsy_robot/meshes/mobile_bot/Wheel_Right.obj" scale="0.1 0.1 0.1"/>
      </geometry>
      <material name="black"/>
    </collision>
    <inertial>
      <origin rpy="0 0 0" xyz="0 0 0"/>
      <mass value="0.329"/>
      <inertia ixx="0.0000129" ixy="0.00" ixz="0.00" iyy="0.000086529" iyz="0.0" izz="0.000086529"/>
    </inertial>
  </link>
  <link name="bin_red">
    <visual>
      <origin rpy="0 0 0" xyz="0 0 0"/>
      <geometry>
        <mesh filename="file:///home/junglator/pandora_ws/install/gypsy_robot/share/gypsy_robot/meshes/mobile_bot/bin.obj"/>
      </geometry>
      <material name="red"/>
    </visual>
    <collision>
      <origin rpy="0 0 0" xyz="0 0 0"/>
      <geometry>
        <mesh filename="file:///home/junglator/pandora_ws/install/gypsy_robot/share/gypsy_robot/meshes/mobile_bot/bin.obj"/>
      </geometry>
      <material name="red"/>
    </collision>
    <inertial>
      <origin rpy="0 0 0" xyz="0 0 0"/>
      <mass value="0.200"/>
      <inertia ixx="0.004" ixy="0.00" ixz="0.00" iyy="0.004" iyz="0.0" izz="0.004"/>
    </inertial>
  </link>
  <link name="bin_green">
    <visual>
      <origin rpy="0 0 0" xyz="0 0 0"/>
      <geometry>
        <mesh filename="file:///home/junglator/pandora_ws/install/gypsy_robot/share/gypsy_robot/meshes/mobile_bot/bin.obj"/>
      </geometry>
      <material name="red"/>
    </visual>
    <collision>
      <origin rpy="0 0 0" xyz="0 0 0"/>
      <geometry>
        <mesh filename="file:///home/junglator/pandora_ws/install/gypsy_robot/share/gypsy_robot/meshes/mobile_bot/bin.obj"/>
      </geometry>
      <material name="red"/>
    </collision>
    <inertial>
      <origin rpy="0 0 0" xyz="0 0 0"/>
      <mass value="0.200"/>
      <inertia ixx="0.004" ixy="0.00" ixz="0.00" iyy="0.004" iyz="0.0" izz="0.004"/>
    </inertial>
  </link>
  <link name="camera_one">
    <visual>
      <origin rpy="0 0 0" xyz="0 0 0"/>
      <geometry>
        <mesh filename="file:///home/junglator/pandora_ws/install/gypsy_robot/share/gypsy_robot/meshes/mobile_bot/realsense.obj" scale="0.001 0.001 0.001"/>
      </geometry>
      <material name="light_grey"/>
    </visual>
    <collision>
      <origin rpy="0 0 0" xyz="0 0 0"/>
      <geometry>
        <mesh filename="file:///home/junglator/pandora_ws/install/gypsy_robot/share/gypsy_robot/meshes/mobile_bot/realsense.obj" scale="0.001 0.001 0.001"/>
      </geometry>
      <material name="light_grey"/>
    </collision>
    <inertial>
      <origin rpy="0 0 0" xyz="0 0 0"/>
      <mass value="0.057836"/>
      <inertia ixx="0.0000046258" ixy="0.00" ixz="0.00" iyy="0.000052583276" iyz="0.0" izz="0.000052583276"/>
    </inertial>
  </link>
  <link name="camera_two">
    <visual>
      <origin rpy="0 0 0" xyz="0 0 0"/>
      <geometry>
        <mesh filename="file:///home/junglator/pandora_ws/install/gypsy_robot/share/gypsy_robot/meshes/mobile_bot/realsense.obj" scale="0.001 0.001 0.001"/>
      </geometry>
      <material name="light_grey"/>
    </visual>
    <collision>
      <origin rpy="0 0 0" xyz="0 0 0"/>
      <geometry>
        <mesh filename="file:///home/junglator/pandora_ws/install/gypsy_robot/share/gypsy_robot/meshes/mobile_bot/realsense.obj" scale="0.001 0.001 0.001"/>
      </geometry>
      <material name="light_grey"/>
    </collision>
    <inertial>
      <origin rpy="0 0 0" xyz="0 0 0"/>
      <mass value="0.057836"/>
      <inertia ixx="0.0000046258" ixy="0.00" ixz="0.00" iyy="0.000052583276" iyz="0.0" izz="0.000052583276"/>
    </inertial>
  </link>
  <!--##################### IMU Link ####################-->
  <link name="imu_link">
    <inertial>
      <mass value="0.001"/>
      <origin rpy="0 0 0" xyz="0 0 0"/>
      <inertia ixx="1e-09" ixy="0.0" ixz="0.0" iyy="1e-09" iyz="0.0" izz="1e-09"/>
    </inertial>
  </link>
  <!--###################### JOINTS ########################-->
  <joint name="upper_left_wheel_joint" type="continuous">
    <origin rpy="0 0 0" xyz="-0.273 0.2237 -0.12"/>
    <parent link="chassis"/>
    <child link="right_upper_wheel"/>
    <axis xyz="1 0 0 "/>
  </joint>
  <joint name="bottom_left_wheel_joint" type="continuous">
    <origin rpy="0 0 0" xyz="-0.273 -0.2237 -0.12"/>
    <parent link="chassis"/>
    <child link="left_bottom_wheel"/>
    <axis xyz="1 0 0"/>
  </joint>
  <joint name="upper_right_wheel_joint" type="continuous">
    <origin rpy="0 0 0" xyz="0.273 0.2237 -0.12"/>
    <parent link="chassis"/>
    <child link="left_upper_wheel"/>
    <axis xyz="1 0 0"/>
  </joint>
  <joint name="bottom_right_wheel_joint" type="continuous">
    <origin rpy="0 0 0" xyz="0.273 -0.2237 -0.12"/>
    <parent link="chassis"/>
    <child link="right_bottom_wheel"/>
    <axis xyz="1 0 0"/>
  </joint>
  <joint name="bin_joint_one" type="fixed">
    <origin rpy="1.5707963267948966 0 0" xyz="0.185 -0.15 0.231"/>
    <parent link="chassis"/>
    <child link="bin_red"/>
    <axis xyz="1 0 0"/>
  </joint>
  <joint name="bin_joint_two" type="fixed">
    <origin rpy="1.5707963267948966 0 0" xyz="-0.185 -0.15 0.231"/>
    <parent link="chassis"/>
    <child link="bin_green"/>
    <axis xyz="1 0 0"/>
  </joint>
  <joint name="camera_joint" type="fixed">
    <origin rpy="-1.5707963267948966 0 0" xyz="0.0 0.395 0.074"/>
    <parent link="chassis"/>
    <child link="camera_one"/>
    <axis xyz="1 0 0"/>
  </joint>
  <joint name="imu_joint" type="fixed">
    <parent link="chassis"/>
    <child link="imu_link"/>
    <origin rpy="0 0 0" xyz="0 0 0"/>
  </joint>
  <ros2_control name="MecanumWheelSystem" type="system">
    <hardware>
      <plugin>gazebo_ros2_control/MecanumWheelSystem</plugin>
    </hardware>
    <joint name="upper_left_wheel_joint">
      <command_interface name="velocity"/>
      <state_interface name="position"/>
      <state_interface name="velocity"/>
      <param name="motor_id">1</param>
    </joint>
    <joint name="bottom_left_wheel_joint">
      <command_interface name="velocity"/>
      <state_interface name="position"/>
      <state_interface name="velocity"/>
      <param name="motor_id">2</param>
    </joint>
    <joint name="upper_right_wheel_joint">
      <command_interface name="velocity"/>
      <state_interface name="position"/>
      <state_interface name="velocity"/>
      <param name="motor_id">3</param>
    </joint>
    <joint name="bottom_right_wheel_joint">
      <command_interface name="velocity"/>
      <state_interface name="position"/>
      <state_interface name="velocity"/>
      <param name="motor_id">4</param>
    </joint>
  </ros2_control>
  <transmission name="front_left_wheel_trans" type="SimpleTransmission">
    <type>transmission_interface/SimpleTransmission</type>
    <actuator name="front_left_wheel_motor">
      <hardwareInterface>hardware_interface/VelocityJointInterface</hardwareInterface>
      <mechanicalReduction>1</mechanicalReduction>
    </actuator>
    <joint name="upper_left_wheel_joint">
      <hardwareInterface>hardware_interface/VelocityJointInterface</hardwareInterface>
    </joint>
  </transmission>
  <transmission name="front_right_wheel_trans" type="SimpleTransmission">
    <type>transmission_interface/SimpleTransmission</type>
    <actuator name="front_right_wheel_motor">
      <hardwareInterface>hardware_interface/VelocityJointInterface</hardwareInterface>
      <mechanicalReduction>1</mechanicalReduction>
    </actuator>
    <joint name="bottom_left_wheel_joint">
      <hardwareInterface>hardware_interface/VelocityJointInterface</hardwareInterface>
    </joint>
  </transmission>
  <transmission name="rear_left_wheel_trans" type="SimpleTransmission">
    <type>transmission_interface/SimpleTransmission</type>
    <actuator name="rear_left_wheel_motor">
      <hardwareInterface>hardware_interface/VelocityJointInterface</hardwareInterface>
      <mechanicalReduction>1</mechanicalReduction>
    </actuator>
    <joint name="upper_right_wheel_joint">
      <hardwareInterface>hardware_interface/VelocityJointInterface</hardwareInterface>
    </joint>
  </transmission>
  <transmission name="rear_right_wheel_trans" type="SimpleTransmission">
    <type>transmission_interface/SimpleTransmission</type>
    <actuator name="rear_right_wheel_motor">
      <hardwareInterface>hardware_interface/VelocityJointInterface</hardwareInterface>
      <mechanicalReduction>1</mechanicalReduction>
    </actuator>
    <joint name="bottom_right_wheel_joint">
      <hardwareInterface>hardware_interface/VelocityJointInterface</hardwareInterface>
    </joint>
  </transmission>
  <gazebo reference="panda_joint1">
    <!-- Needed for ODE to output external wrenches on joints -->
    <provideFeedback>true</provideFeedback>
  </gazebo>
  <transmission name="panda_joint1_transmission">
    <type>transmission_interface/SimpleTransmission</type>
    <joint name="panda_joint1">
      <hardwareInterface>hardware_interface/EffortJointInterface</hardwareInterface>
    </joint>
    <actuator name="panda_joint1_motor">
      <hardwareInterface>hardware_interface/EffortJointInterface</hardwareInterface>
    </actuator>
  </transmission>
  <gazebo reference="panda_joint2">
    <!-- Needed for ODE to output external wrenches on joints -->
    <provideFeedback>true</provideFeedback>
  </gazebo>
  <transmission name="panda_joint2_transmission">
    <type>transmission_interface/SimpleTransmission</type>
    <joint name="panda_joint2">
      <hardwareInterface>hardware_interface/EffortJointInterface</hardwareInterface>
    </joint>
    <actuator name="panda_joint2_motor">
      <hardwareInterface>hardware_interface/EffortJointInterface</hardwareInterface>
    </actuator>
  </transmission>
  <gazebo reference="panda_joint3">
    <!-- Needed for ODE to output external wrenches on joints -->
    <provideFeedback>true</provideFeedback>
  </gazebo>
  <transmission name="panda_joint3_transmission">
    <type>transmission_interface/SimpleTransmission</type>
    <joint name="panda_joint3">
      <hardwareInterface>hardware_interface/EffortJointInterface</hardwareInterface>
    </joint>
    <actuator name="panda_joint3_motor">
      <hardwareInterface>hardware_interface/EffortJointInterface</hardwareInterface>
    </actuator>
  </transmission>
  <gazebo reference="panda_joint4">
    <!-- Needed for ODE to output external wrenches on joints -->
    <provideFeedback>true</provideFeedback>
  </gazebo>
  <transmission name="panda_joint4_transmission">
    <type>transmission_interface/SimpleTransmission</type>
    <joint name="panda_joint4">
      <hardwareInterface>hardware_interface/EffortJointInterface</hardwareInterface>
    </joint>
    <actuator name="panda_joint4_motor">
      <hardwareInterface>hardware_interface/EffortJointInterface</hardwareInterface>
    </actuator>
  </transmission>
  <gazebo reference="panda_joint5">
    <!-- Needed for ODE to output external wrenches on joints -->
    <provideFeedback>true</provideFeedback>
  </gazebo>
  <transmission name="panda_joint5_transmission">
    <type>transmission_interface/SimpleTransmission</type>
    <joint name="panda_joint5">
      <hardwareInterface>hardware_interface/EffortJointInterface</hardwareInterface>
    </joint>
    <actuator name="panda_joint5_motor">
      <hardwareInterface>hardware_interface/EffortJointInterface</hardwareInterface>
    </actuator>
  </transmission>
  <gazebo reference="panda_joint6">
    <!-- Needed for ODE to output external wrenches on joints -->
    <provideFeedback>true</provideFeedback>
  </gazebo>
  <transmission name="panda_joint6_transmission">
    <type>transmission_interface/SimpleTransmission</type>
    <joint name="panda_joint6">
      <hardwareInterface>hardware_interface/EffortJointInterface</hardwareInterface>
    </joint>
    <actuator name="panda_joint6_motor">
      <hardwareInterface>hardware_interface/EffortJointInterface</hardwareInterface>
    </actuator>
  </transmission>
  <gazebo reference="panda_joint7">
    <!-- Needed for ODE to output external wrenches on joints -->
    <provideFeedback>true</provideFeedback>
  </gazebo>
  <transmission name="panda_joint7_transmission">
    <type>transmission_interface/SimpleTransmission</type>
    <joint name="panda_joint7">
      <hardwareInterface>hardware_interface/EffortJointInterface</hardwareInterface>
    </joint>
    <actuator name="panda_joint7_motor">
      <hardwareInterface>hardware_interface/EffortJointInterface</hardwareInterface>
    </actuator>
  </transmission>
  <transmission name="panda_leftfinger_transmission">
    <type>transmission_interface/SimpleTransmission</type>
    <joint name="finger_joint1">
      <hardwareInterface>hardware_interface/EffortJointInterface</hardwareInterface>
    </joint>
    <actuator name="leftfinger_actuator">
      <hardwareInterface>hardware_interface/EffortJointInterface</hardwareInterface>
    </actuator>
  </transmission>
  <transmission name="panda_rightfinger_transmission">
    <type>transmission_interface/SimpleTransmission</type>
    <joint name="finger_joint2">
      <hardwareInterface>hardware_interface/EffortJointInterface</hardwareInterface>
    </joint>
    <actuator name="rightfinger_actuator">
      <hardwareInterface>hardware_interface/EffortJointInterface</hardwareInterface>
    </actuator>
  </transmission>
  <transmission name="panda_franka_state">
    <type>franka_hw/FrankaStateInterface</type>
    <joint name="panda_joint1">
      <hardwareInterface>franka_hw/FrankaStateInterface</hardwareInterface>
    </joint>
    <joint name="panda_joint2">
      <hardwareInterface>franka_hw/FrankaStateInterface</hardwareInterface>
    </joint>
    <joint name="panda_joint3">
      <hardwareInterface>franka_hw/FrankaStateInterface</hardwareInterface>
    </joint>
    <joint name="panda_joint4">
      <hardwareInterface>franka_hw/FrankaStateInterface</hardwareInterface>
    </joint>
    <joint name="panda_joint5">
      <hardwareInterface>franka_hw/FrankaStateInterface</hardwareInterface>
    </joint>
    <joint name="panda_joint6">
      <hardwareInterface>franka_hw/FrankaStateInterface</hardwareInterface>
    </joint>
    <joint name="panda_joint7">
      <hardwareInterface>franka_hw/FrankaStateInterface</hardwareInterface>
    </joint>
    <actuator name="panda_motor1">
      <hardwareInterface>franka_hw/FrankaStateInterface</hardwareInterface>
    </actuator>
    <actuator name="panda_motor2">
      <hardwareInterface>franka_hw/FrankaStateInterface</hardwareInterface>
    </actuator>
    <actuator name="panda_motor3">
      <hardwareInterface>franka_hw/FrankaStateInterface</hardwareInterface>
    </actuator>
    <actuator name="panda_motor4">
      <hardwareInterface>franka_hw/FrankaStateInterface</hardwareInterface>
    </actuator>
    <actuator name="panda_motor5">
      <hardwareInterface>franka_hw/FrankaStateInterface</hardwareInterface>
    </actuator>
    <actuator name="panda_motor6">
      <hardwareInterface>franka_hw/FrankaStateInterface</hardwareInterface>
    </actuator>
    <actuator name="panda_motor7">
      <hardwareInterface>franka_hw/FrankaStateInterface</hardwareInterface>
    </actuator>
  </transmission>
  <transmission name="panda_franka_model">
    <type>franka_hw/FrankaModelInterface</type>
    <joint name="panda_joint1">
      <role>root</role>
      <hardwareInterface>franka_hw/FrankaModelInterface</hardwareInterface>
    </joint>
    <joint name="panda_joint8">
      <role>tip</role>
      <hardwareInterface>franka_hw/FrankaModelInterface</hardwareInterface>
    </joint>
    <actuator name="panda_joint1_motor_root">
      <hardwareInterface>franka_hw/FrankaModelInterface</hardwareInterface>
    </actuator>
    <actuator name="panda_joint8_motor_tip">
      <hardwareInterface>franka_hw/FrankaModelInterface</hardwareInterface>
    </actuator>
  </transmission>
  <gazebo>
    <self_collide>true</self_collide>
  </gazebo>
  <!--ros_control plugin-->
  <gazebo>
    <plugin filename="libgazebo_ros_control.so" name="gazebo_ros_control">
      <robotNamespace>panda</robotNamespace>
      <robotSimType>gazebo_ros_control/DefaultRobotHWSim</robotSimType>
      <controlPeriod>0.001</controlPeriod>
      <legacyModeNS>false</legacyModeNS>
    </plugin>
  </gazebo>
  <!--joint state plugin-->
  <gazebo>
    <plugin filename="libgazebo_ros_joint_state_publisher.so" name="joint_state_publisher">
      <jointName>panda_joint0,panda_joint1,panda_joint2,panda_joint3,panda_joint4,
                    panda_joint5,panda_joint6,panda_joint7,finger_joint1,finger_joint1</jointName>
    </plugin>
  </gazebo>
  <!--grasp plugin-->
  <gazebo>
    <plugin filename="libgazebo_grasp_fix.so" name="gazebo_grasp_fix">
      <arm>
        <arm_name>panda</arm_name>
        <palm_link>hand</palm_link>
        <gripper_link>leftfinger</gripper_link>
        <gripper_link>rightfinger</gripper_link>
      </arm>
      <forces_angle_tolerance>100</forces_angle_tolerance>
      <update_rate>4</update_rate>
      <grip_count_threshold>4</grip_count_threshold>
      <max_grip_count>8</max_grip_count>
      <release_tolerance>0.003</release_tolerance>
      <disable_collisions_on_attach>false</disable_collisions_on_attach>
      <contact_topic>__default_topic__</contact_topic>
    </plugin>
  </gazebo>
  <!--########################## MOBILE BOT ################################-->
  <gazebo reference="chassis">
    <material>Gazebo/Grey</material>
  </gazebo>
  <gazebo reference="bin_one">
    <material>Gazebo/Red</material>
  </gazebo>
  <gazebo reference="bin_two">
    <material>Gazebo/Green</material>
  </gazebo>
  <gazebo reference="left_upper_wheel">
    <material>Gazebo/Black</material>
  </gazebo>
  <gazebo reference="left_bottom_wheel">
    <material>Gazebo/Black</material>
  </gazebo>
  <gazebo reference="right_upper_wheel">
    <material>Gazebo/Black</material>
  </gazebo>
  <gazebo reference="right_botttom_wheel">
    <material>Gazebo/Black</material>
  </gazebo>
  <gazebo reference="camera_one">
    <material>Gazebo/FlatBlack</material>
  </gazebo>
  <gazebo reference="camera_two">
    <material>Gazebo/FlatBlack</material>
  </gazebo>
  <!--################################# PANDA ARM ########################################-->
  <gazebo reference="panda_link0">
    <material>Gazebo/Orange</material>
  </gazebo>
  <gazebo reference="panda_link1">
    <material>Gazebo/Orange</material>
  </gazebo>
  <gazebo reference="panda_link2">
    <material>Gazebo/Orange</material>
  </gazebo>
  <gazebo reference="panda_link3">
    <material>Gazebo/Orange</material>
  </gazebo>
  <gazebo reference="panda_link4">
    <material>Gazebo/Orange</material>
  </gazebo>
  <gazebo reference="panda_link5">
    <material>Gazebo/Orange</material>
  </gazebo>
  <gazebo reference="panda_link6">
    <material>$panda_body_color}</material>
  </gazebo>
  <gazebo reference="panda_link7">
    <material>Gazebo/Orange</material>
  </gazebo>
  <gazebo reference="hand">
    <material>Gazebo/Orange</material>
  </gazebo>
  <gazebo reference="leftfinger">
    <material>Gazebo/Black</material>
  </gazebo>
  <gazebo reference="rightfinger">
    <material>Gazebo/Black</material>
  </gazebo>
  <gazebo reference="chassis">
    <gravity>true</gravity>
  </gazebo>
  <!--############################### IMU LINK ###############################-->
  <gazebo reference="imu_link">
    <gravity>true</gravity>
    <sensor name="imu_sensor" type="imu">
      <always_on>true</always_on>
      <plugin filename="libgazebo_ros_imu_sensor.so" name="imu_plugin">
        <updateRate>30.0</updateRate>
        <bodyName>imu_link</bodyName>
        <topicName>imu/data</topicName>
        <frameName>imu_link</frameName>
        <gaussianNoise>0.001</gaussianNoise>
        <xyzOffset>0 0 0</xyzOffset>
        <rpyOffset>0 0 0</rpyOffset>
        <initialOrientationAsReference>false</initialOrientationAsReference>
      </plugin>
      <pose>0 0 0 0 0 0</pose>
    </sensor>
  </gazebo>
  <!--################### DEPTH CAMERA PLUGIN (Realsense D435i) ##################-->
  <gazebo reference="camera_one_color_frame">
    <sensor name="camera1" type="camera">
      <update_rate>30</update_rate>
      <camera name="__deafult__">
        <horizontal_fov>1.047198</horizontal_fov>
        <image>
          <width>640</width>
          <height>480</height>
          <format>RGB_INT8</format>
        </image>
        <clip>
          <near>0.1</near>
          <far>100</far>
        </clip>
        <noise>
          <type>gaussian</type>
          <mean>0.0</mean>
          <stddev>0.007</stddev>
        </noise>
      </camera>
      <always_on>1</always_on>
      <visualize>0</visualize>
    </sensor>
  </gazebo>
  <gazebo reference="camera_one_infra_frame">
    <sensor name="ir1" type="camera">
      <update_rate>30</update_rate>
      <camera name="__deafult__">
        <horizontal_fov>1.047198</horizontal_fov>
        <image>
          <width>640</width>
          <height>480</height>
          <format>L_INT8</format>
        </image>
        <clip>
          <near>0.1</near>
          <far>100</far>
        </clip>
        <noise>
          <type>gaussian</type>
          <mean>0.0</mean>
          <stddev>0.007</stddev>
        </noise>
      </camera>
      <always_on>1</always_on>
      <visualize>0</visualize>
    </sensor>
  </gazebo>
  <gazebo reference="camera_one_depth_frame">
    <sensor name="depth" type="depth">
      <update_rate>30</update_rate>
      <camera name="__deafult__">
        <horizontal_fov>1.047198</horizontal_fov>
        <image>
          <width>640</width>
          <height>480</height>
        </image>
        <clip>
          <near>0.1</near>
          <far>100</far>
        </clip>
        <noise>
          <type>gaussian</type>
          <mean>0.0</mean>
          <stddev>0.007</stddev>
        </noise>
      </camera>
      <always_on>1</always_on>
      <visualize>0</visualize>
    </sensor>
  </gazebo>
  <gazebo>
    <plugin filename="librealsense_gazebo_plugin.so" name="camera">
      <depthUpdateRate>30</depthUpdateRate>
      <colorUpdateRate>30</colorUpdateRate>
      <infraredUpdateRate>30</infraredUpdateRate>
      <depthTopicName>depth/image_raw</depthTopicName>
      <depthCameraInfoTopicName>depth/camera_info</depthCameraInfoTopicName>
      <colorTopicName>color/image_raw</colorTopicName>
      <colorCameraInfoTopicName>color/camera_info</colorCameraInfoTopicName>
      <infrared1TopicName>infrared/image_raw</infrared1TopicName>
      <infrared1CameraInfoTopicName>infrared/camera_info</infrared1CameraInfoTopicName>
      <infrared2TopicName>infrared2/image_raw</infrared2TopicName>
      <infrared2CameraInfoTopicName>infrared2/camera_info</infrared2CameraInfoTopicName>
      <colorOpticalframeName>camera_color_optical_frame</colorOpticalframeName>
      <depthOpticalframeName>camera_depth_optical_frame</depthOpticalframeName>
      <infrared1OpticalframeName>camera_left_ir_optical_frame</infrared1OpticalframeName>
      <infrared2OpticalframeName>camera_right_ir_optical_frame</infrared2OpticalframeName>
      <rangeMinDepth>0.1</rangeMinDepth>
      <rangeMaxDepth>10</rangeMaxDepth>
      <pointCloud>1</pointCloud>
      <pointCloudTopicName>depth/color/points</pointCloudTopicName>
      <pointCloudCutoff>0.15</pointCloudCutoff>
      <pointCloudCutoffMax>10</pointCloudCutoffMax>
    </plugin>
  </gazebo>
  <gazebo reference="camera_one_gyro_frame">
    <gravity>true</gravity>
    <sensor name="imu_sensor" type="imu">
      <always_on>true</always_on>
      <visualize>false</visualize>
      <plugin filename="libgazebo_ros_imu_sensor.so" name="imu_plugin">
        <topicName>camera/imu/data</topicName>
        <bodyName>camera_gyro_frame</bodyName>
        <updateRateHZ>50.0</updateRateHZ>
        <gaussianNoise>0.001</gaussianNoise>
        <xyzOffset>0 0 0</xyzOffset>
        <rpyOffset>0 0 0</rpyOffset>
        <frameName>camera_gyro_frame</frameName>
        <initialOrientationAsReference>false</initialOrientationAsReference>
      </plugin>
      <pose>0 0 0 0 0 0</pose>
    </sensor>
  </gazebo>
  <!--################################## MECANUM WHEEL ###############################-->
  <gazebo>
    <plugin filename="libgazebo_ros_planar_move.so" name="mecanum_controller">
      <commandTopic>cmd_vel</commandTopic>
      <odometryTopic>odom</odometryTopic>
      <odometryFrame>odom</odometryFrame>
      <odometryRate>100.0</odometryRate>
      <update_rate>100</update_rate>
      <publish_rate>10</publish_rate>
      <robotBaseFrame>base_footprint</robotBaseFrame>
      <!--robot_base_frame>base_footprint</robot_base_frame-->
      <publishTF>false</publishTF>
      <covariance_x>0.0001</covariance_x>
      <covariance_y>0.0001</covariance_y>
      <covariance_yaw>0.01</covariance_yaw>
    </plugin>
  </gazebo>
  <gazebo reference="upper_left_wheel">
    <mu1 value="1.0"/>
    <mu2 value="1.0"/>
    <kp value="10000000.0"/>
    <kd value="1.0"/>
    <fdir1 value="1 0 0"/>
  </gazebo>
  <gazebo reference="upper_right_wheel">
    <mu1 value="1.0"/>
    <mu2 value="1.0"/>
    <kp value="10000000.0"/>
    <kd value="1.0"/>
    <fdir1 value="1 0 0"/>
  </gazebo>
  <gazebo reference="bottom_left_wheel">
    <mu1 value="1.0"/>
    <mu2 value="1.0"/>
    <kp value="10000000.0"/>
    <kd value="1.0"/>
    <fdir1 value="1 0 0"/>
  </gazebo>
  <gazebo reference="bottom_right_wheel">
    <mu1 value="1.0"/>
    <mu2 value="1.0"/>
    <kp value="10000000.0"/>
    <kd value="1.0"/>
    <fdir1 value="1 0 0"/>
  </gazebo>
  <gazebo reference="panda_link0">
    <mu1>0.2</mu1>
    <mu2>0.2</mu2>
    <gravity>true</gravity>
    <self_collide>true</self_collide>
  </gazebo>
  <gazebo reference="panda_link1">
    <mu1>0.2</mu1>
    <mu2>0.2</mu2>
    <gravity>true</gravity>
    <self_collide>true</self_collide>
  </gazebo>
  <gazebo reference="panda_link2">
    <mu1>0.2</mu1>
    <mu2>0.2</mu2>
    <gravity>true</gravity>
    <self_collide>true</self_collide>
  </gazebo>
  <gazebo reference="panda_link3">
    <mu1>0.2</mu1>
    <mu2>0.2</mu2>
    <gravity>true</gravity>
    <self_collide>true</self_collide>
  </gazebo>
  <gazebo reference="panda_link4">
    <mu1>0.2</mu1>
    <mu2>0.2</mu2>
    <gravity>true</gravity>
    <self_collide>true</self_collide>
  </gazebo>
  <gazebo reference="panda_link5">
    <mu1>0.2</mu1>
    <mu2>0.2</mu2>
    <gravity>true</gravity>
    <self_collide>true</self_collide>
  </gazebo>
  <gazebo reference="panda_link6">
    <mu1>0.2</mu1>
    <mu2>0.2</mu2>
    <gravity>true</gravity>
    <self_collide>true</self_collide>
  </gazebo>
  <gazebo reference="panda_link7">
    <mu1>0.2</mu1>
    <mu2>0.2</mu2>
    <gravity>true</gravity>
    <self_collide>true</self_collide>
  </gazebo>
  <gazebo reference="panda_link8">
    <gravity>true</gravity>
    <self_collide>true</self_collide>
  </gazebo>
  <gazebo reference="hand">
    <mu1>0.2</mu1>
    <mu2>0.2</mu2>
    <gravity>true</gravity>
    <self_collide>true</self_collide>
  </gazebo>
  <gazebo reference="leftfinger">
    <kp>1000000.0</kp>
    <kd>1.0</kd>
    <mu1>30.0</mu1>
    <mu2>30.0</mu2>
    <gravity>true</gravity>
    <self_collide>true</self_collide>
  </gazebo>
  <gazebo reference="rightfinger">
    <kp>1000000.0</kp>
    <kd>1.0</kd>
    <mu1>30.0</mu1>
    <mu2>30.0</mu2>
    <gravity>true</gravity>
    <self_collide>true</self_collide>
  </gazebo>
  <!--########################################################################################-->
  <link name="base_footprint"/>
  <joint name="base_link_joint" type="fixed">
    <origin rpy="0 0 1.5707963267948966" xyz="0 0 0.15"/>
    <parent link="base_footprint"/>
    <child link="chassis"/>
    <axis xyz="0 0 0"/>
  </joint>
  <joint name="arm_joint" type="fixed">
    <origin rpy="0 0 1.5707963267948966" xyz="0 0.3 0.1325"/>
    <parent link="chassis"/>
    <child link="panda_link0"/>
  </joint>
  <joint name="arm_camera_joint" type="fixed">
    <origin rpy="0 0 0.7853981633974483" xyz="0.04 -0.032 0.03"/>
    <parent link="panda_link8"/>
    <child link="camera_two"/>
    <axis xyz="1 0 0"/>
  </joint>
</robot>
