<sdf version='1.7'>
  <model name='gypsy'>
    <link name='base_footprint'>
      <inertial>
        <pose>0.018625 2e-06 0.189807 0 -0 0</pose>
        <mass>36.4546</mass>
        <inertia>
          <ixx>1.97374</ixx>
          <ixy>2.5305e-05</ixy>
          <ixz>-0.141918</ixz>
          <iyy>3.89306</iyy>
          <iyz>-2.08085e-05</iyz>
          <izz>3.34303</izz>
        </inertia>
      </inertial>
      <collision name='base_footprint_fixed_joint_lump__chassis_collision'>
        <pose>0 0 0.15 0 -0 1.5708</pose>
        <geometry>
          <mesh>
            <scale>1 1 1</scale>
            <uri>file:///home/junglator/pandora_ws/install/gypsy_robot/share/gypsy_robot/meshes/mobile_bot/chassis_o.obj</uri>
          </mesh>
        </geometry>
        <surface>
          <contact>
            <ode/>
          </contact>
          <friction>
            <ode/>
          </friction>
        </surface>
      </collision>
      <collision name='base_footprint_fixed_joint_lump__panda_link0_collision_1'>
        <pose>-0.3 0 0.2825 0 -0 3.14159</pose>
        <geometry>
          <mesh>
            <scale>1 1 1</scale>
            <uri>file:///home/junglator/pandora_ws/install/gypsy_robot/share/gypsy_robot/meshes/panda_arm/link0.obj</uri>
          </mesh>
        </geometry>
        <surface>
          <contact>
            <ode/>
          </contact>
          <friction>
            <ode/>
          </friction>
        </surface>
      </collision>
      <collision name='base_footprint_fixed_joint_lump__bin_red_collision_2'>
        <pose>0.15 0.185 0.381 1.5708 -0 1.5708</pose>
        <geometry>
          <mesh>
            <scale>1 1 1</scale>
            <uri>file:///home/junglator/pandora_ws/install/gypsy_robot/share/gypsy_robot/meshes/mobile_bot/bin.obj</uri>
          </mesh>
        </geometry>
      </collision>
      <collision name='base_footprint_fixed_joint_lump__bin_green_collision_3'>
        <pose>0.15 -0.185 0.381 1.5708 -0 1.5708</pose>
        <geometry>
          <mesh>
            <scale>1 1 1</scale>
            <uri>file:///home/junglator/pandora_ws/install/gypsy_robot/share/gypsy_robot/meshes/mobile_bot/bin.obj</uri>
          </mesh>
        </geometry>
      </collision>
      <collision name='base_footprint_fixed_joint_lump__camera_one_collision_4'>
        <pose>-0.395 0 0.224 -1.5708 0 1.5708</pose>
        <geometry>
          <mesh>
            <scale>0.001 0.001 0.001</scale>
            <uri>file:///home/junglator/pandora_ws/install/gypsy_robot/share/gypsy_robot/meshes/mobile_bot/realsense.obj</uri>
          </mesh>
        </geometry>
        <surface>
          <contact>
            <ode/>
          </contact>
          <friction>
            <ode/>
          </friction>
        </surface>
      </collision>
      <visual name='base_footprint_fixed_joint_lump__chassis_visual'>
        <pose>0 0 0.15 0 -0 1.5708</pose>
        <geometry>
          <mesh>
            <scale>1 1 1</scale>
            <uri>file:///home/junglator/pandora_ws/install/gypsy_robot/share/gypsy_robot/meshes/mobile_bot/chassis_o.obj</uri>
          </mesh>
        </geometry>
        <material>
          <script>
            <name>Gazebo/Grey</name>
            <uri>file://media/materials/scripts/gazebo.material</uri>
          </script>
        </material>
      </visual>
      <visual name='base_footprint_fixed_joint_lump__panda_link0_visual_1'>
        <pose>-0.3 0 0.2825 0 -0 3.14159</pose>
        <geometry>
          <mesh>
            <scale>1 1 1</scale>
            <uri>file:///home/junglator/pandora_ws/install/gypsy_robot/share/gypsy_robot/meshes/panda_arm/link0.obj</uri>
          </mesh>
        </geometry>
        <material>
          <script>
            <name>Gazebo/Orange</name>
            <uri>file://media/materials/scripts/gazebo.material</uri>
          </script>
        </material>
      </visual>
      <visual name='base_footprint_fixed_joint_lump__bin_red_visual_2'>
        <pose>0.15 0.185 0.381 1.5708 -0 1.5708</pose>
        <geometry>
          <mesh>
            <scale>1 1 1</scale>
            <uri>file:///home/junglator/pandora_ws/install/gypsy_robot/share/gypsy_robot/meshes/mobile_bot/bin.obj</uri>
          </mesh>
        </geometry>
      </visual>
      <visual name='base_footprint_fixed_joint_lump__bin_green_visual_3'>
        <pose>0.15 -0.185 0.381 1.5708 -0 1.5708</pose>
        <geometry>
          <mesh>
            <scale>1 1 1</scale>
            <uri>file:///home/junglator/pandora_ws/install/gypsy_robot/share/gypsy_robot/meshes/mobile_bot/bin.obj</uri>
          </mesh>
        </geometry>
      </visual>
      <visual name='base_footprint_fixed_joint_lump__camera_one_visual_4'>
        <pose>-0.395 0 0.224 -1.5708 0 1.5708</pose>
        <geometry>
          <mesh>
            <scale>0.001 0.001 0.001</scale>
            <uri>file:///home/junglator/pandora_ws/install/gypsy_robot/share/gypsy_robot/meshes/mobile_bot/realsense.obj</uri>
          </mesh>
        </geometry>
        <material>
          <script>
            <name>Gazebo/FlatBlack</name>
            <uri>file://media/materials/scripts/gazebo.material</uri>
          </script>
        </material>
      </visual>
      <gravity>1</gravity>
      <gravity>1</gravity>
      <self_collide>1</self_collide>
      <gravity>1</gravity>
      <sensor name='imu_sensor' type='imu'>
        <always_on>1</always_on>
        <plugin name='imu_plugin' filename='libgazebo_ros_imu_sensor.so'>
          <updateRate>30.0</updateRate>
          <bodyName>imu_link</bodyName>
          <topicName>imu/data</topicName>
          <frameName>imu_link</frameName>
          <gaussianNoise>0.001</gaussianNoise>
          <xyzOffset>0 0 0</xyzOffset>
          <rpyOffset>0 0 0</rpyOffset>
          <initialOrientationAsReference>0</initialOrientationAsReference>
        </plugin>
        <pose>0 0 0.15 0 -0 1.5708</pose>
      </sensor>
    </link>
    <joint name='panda_joint1' type='revolute'>
      <pose relative_to='base_footprint'>-0.3 0 0.6155 0 -0 3.14159</pose>
      <parent>base_footprint</parent>
      <child>panda_link1</child>
      <axis>
        <xyz>0 0 1</xyz>
        <limit>
          <lower>-2.9671</lower>
          <upper>2.9671</upper>
          <effort>87</effort>
          <velocity>2.5</velocity>
        </limit>
        <dynamics>
          <damping>0.003</damping>
          <friction>0</friction>
          <spring_reference>0</spring_reference>
          <spring_stiffness>0</spring_stiffness>
        </dynamics>
      </axis>
      <physics>
        <provide_feedback>1</provide_feedback>
        <ode>
          <limit>
            <cfm>0</cfm>
            <erp>0.2</erp>
          </limit>
          <provide_feedback>1</provide_feedback>
        </ode>
      </physics>
    </joint>
    <link name='panda_link1'>
      <pose relative_to='panda_joint1'>0 0 0 0 -0 0</pose>
      <inertial>
        <pose>0.008212 -0.026532 -0.047138 0 -0 0</pose>
        <mass>4.97068</mass>
        <inertia>
          <ixx>0.701415</ixx>
          <ixy>-0.000639816</ixy>
          <ixz>0.00783641</ixz>
          <iyy>0.704801</iyy>
          <iyz>0.0107454</iyz>
          <izz>0.0101111</izz>
        </inertia>
      </inertial>
      <collision name='panda_link1_collision'>
        <pose>0 0 0 0 -0 0</pose>
        <geometry>
          <mesh>
            <scale>1 1 1</scale>
            <uri>file:///home/junglator/pandora_ws/install/gypsy_robot/share/gypsy_robot/meshes/panda_arm/link1.obj</uri>
          </mesh>
        </geometry>
        <surface>
          <contact>
            <ode/>
          </contact>
          <friction>
            <ode/>
          </friction>
        </surface>
      </collision>
      <visual name='panda_link1_visual'>
        <pose>0 0 0 0 -0 0</pose>
        <geometry>
          <mesh>
            <scale>1 1 1</scale>
            <uri>file:///home/junglator/pandora_ws/install/gypsy_robot/share/gypsy_robot/meshes/panda_arm/link1.obj</uri>
          </mesh>
        </geometry>
        <material>
          <script>
            <name>Gazebo/Orange</name>
            <uri>file://media/materials/scripts/gazebo.material</uri>
          </script>
        </material>
      </visual>
      <gravity>1</gravity>
      <self_collide>1</self_collide>
    </link>
    <joint name='panda_joint2' type='revolute'>
      <pose relative_to='panda_link1'>0 0 0 -1.5708 0 0</pose>
      <parent>panda_link1</parent>
      <child>panda_link2</child>
      <axis>
        <xyz>0 0 1</xyz>
        <limit>
          <lower>-1.8326</lower>
          <upper>1.8326</upper>
          <effort>87</effort>
          <velocity>2.5</velocity>
        </limit>
        <dynamics>
          <damping>0.003</damping>
          <friction>0</friction>
          <spring_reference>0</spring_reference>
          <spring_stiffness>0</spring_stiffness>
        </dynamics>
      </axis>
      <physics>
        <provide_feedback>1</provide_feedback>
        <ode>
          <limit>
            <cfm>0</cfm>
            <erp>0.2</erp>
          </limit>
          <provide_feedback>1</provide_feedback>
        </ode>
      </physics>
    </joint>
    <link name='panda_link2'>
      <pose relative_to='panda_joint2'>0 0 0 0 -0 0</pose>
      <inertial>
        <pose>-0.008844 -0.027532 -0.000559 0 -0 0</pose>
        <mass>0.647124</mass>
        <inertia>
          <ixx>0.0120282</ixx>
          <ixy>-0.00517696</ixy>
          <ixz>0.0284167</ixz>
          <iyy>0.034001</iyy>
          <iyz>-0.0034873</iyz>
          <izz>0.0260055</izz>
        </inertia>
      </inertial>
      <collision name='panda_link2_collision'>
        <pose>0 0 0 0 -0 0</pose>
        <geometry>
          <mesh>
            <scale>1 1 1</scale>
            <uri>file:///home/junglator/pandora_ws/install/gypsy_robot/share/gypsy_robot/meshes/panda_arm/link2.obj</uri>
          </mesh>
        </geometry>
        <surface>
          <contact>
            <ode/>
          </contact>
          <friction>
            <ode/>
          </friction>
        </surface>
      </collision>
      <visual name='panda_link2_visual'>
        <pose>0 0 0 0 -0 0</pose>
        <geometry>
          <mesh>
            <scale>1 1 1</scale>
            <uri>file:///home/junglator/pandora_ws/install/gypsy_robot/share/gypsy_robot/meshes/panda_arm/link2.obj</uri>
          </mesh>
        </geometry>
        <material>
          <script>
            <name>Gazebo/Orange</name>
            <uri>file://media/materials/scripts/gazebo.material</uri>
          </script>
        </material>
      </visual>
      <gravity>1</gravity>
      <self_collide>1</self_collide>
    </link>
    <joint name='panda_joint3' type='revolute'>
      <pose relative_to='panda_link2'>0 -0.316 0 1.5708 -0 0</pose>
      <parent>panda_link2</parent>
      <child>panda_link3</child>
      <axis>
        <xyz>0 0 1</xyz>
        <limit>
          <lower>-2.9671</lower>
          <upper>2.9671</upper>
          <effort>87</effort>
          <velocity>2.5</velocity>
        </limit>
        <dynamics>
          <damping>0.003</damping>
          <friction>0</friction>
          <spring_reference>0</spring_reference>
          <spring_stiffness>0</spring_stiffness>
        </dynamics>
      </axis>
      <physics>
        <provide_feedback>1</provide_feedback>
        <ode>
          <limit>
            <cfm>0</cfm>
            <erp>0.2</erp>
          </limit>
          <provide_feedback>1</provide_feedback>
        </ode>
      </physics>
    </joint>
    <link name='panda_link3'>
      <pose relative_to='panda_joint3'>0 0 0 0 -0 0</pose>
      <inertial>
        <pose>0.02834 0.037618 -0.067209 0 -0 0</pose>
        <mass>3.22834</mass>
        <inertia>
          <ixx>0.0358656</ixx>
          <ixy>-0.00489817</ixy>
          <ixz>-0.0168365</ixz>
          <iyy>0.0410624</iyy>
          <iyz>-0.0129579</iyz>
          <izz>0.00729542</izz>
        </inertia>
      </inertial>
      <collision name='panda_link3_collision'>
        <pose>0 0 0 0 -0 0</pose>
        <geometry>
          <mesh>
            <scale>1 1 1</scale>
            <uri>file:///home/junglator/pandora_ws/install/gypsy_robot/share/gypsy_robot/meshes/panda_arm/link3.obj</uri>
          </mesh>
        </geometry>
        <surface>
          <contact>
            <ode/>
          </contact>
          <friction>
            <ode/>
          </friction>
        </surface>
      </collision>
      <visual name='panda_link3_visual'>
        <pose>0 0 0 0 -0 0</pose>
        <geometry>
          <mesh>
            <scale>1 1 1</scale>
            <uri>file:///home/junglator/pandora_ws/install/gypsy_robot/share/gypsy_robot/meshes/panda_arm/link3.obj</uri>
          </mesh>
        </geometry>
        <material>
          <script>
            <name>Gazebo/Orange</name>
            <uri>file://media/materials/scripts/gazebo.material</uri>
          </script>
        </material>
      </visual>
      <gravity>1</gravity>
      <self_collide>1</self_collide>
    </link>
    <joint name='panda_joint4' type='revolute'>
      <pose relative_to='panda_link3'>0.0825 0 0 1.5708 -0 0</pose>
      <parent>panda_link3</parent>
      <child>panda_link4</child>
      <axis>
        <xyz>0 0 1</xyz>
        <limit>
          <lower>-3.1416</lower>
          <upper>-0.4</upper>
          <effort>87</effort>
          <velocity>2.5</velocity>
        </limit>
        <dynamics>
          <damping>0.003</damping>
          <friction>0</friction>
          <spring_reference>0</spring_reference>
          <spring_stiffness>0</spring_stiffness>
        </dynamics>
      </axis>
      <physics>
        <provide_feedback>1</provide_feedback>
        <ode>
          <limit>
            <cfm>0</cfm>
            <erp>0.2</erp>
          </limit>
          <provide_feedback>1</provide_feedback>
        </ode>
      </physics>
    </joint>
    <link name='panda_link4'>
      <pose relative_to='panda_joint4'>0 0 0 0 -0 0</pose>
      <inertial>
        <pose>-0.052864 0.102868 0.027231 0 -0 0</pose>
        <mass>3.58771</mass>
        <inertia>
          <ixx>0.0237133</ixx>
          <ixy>0.0194949</ixy>
          <ixz>-0.000418068</ixz>
          <iyy>0.0167776</iyy>
          <iyz>0.00736882</iyz>
          <izz>0.0332345</izz>
        </inertia>
      </inertial>
      <collision name='panda_link4_collision'>
        <pose>0 0 0 0 -0 0</pose>
        <geometry>
          <mesh>
            <scale>1 1 1</scale>
            <uri>file:///home/junglator/pandora_ws/install/gypsy_robot/share/gypsy_robot/meshes/panda_arm/link4.obj</uri>
          </mesh>
        </geometry>
        <surface>
          <contact>
            <ode/>
          </contact>
          <friction>
            <ode/>
          </friction>
        </surface>
      </collision>
      <visual name='panda_link4_visual'>
        <pose>0 0 0 0 -0 0</pose>
        <geometry>
          <mesh>
            <scale>1 1 1</scale>
            <uri>file:///home/junglator/pandora_ws/install/gypsy_robot/share/gypsy_robot/meshes/panda_arm/link4.obj</uri>
          </mesh>
        </geometry>
        <material>
          <script>
            <name>Gazebo/Orange</name>
            <uri>file://media/materials/scripts/gazebo.material</uri>
          </script>
        </material>
      </visual>
      <gravity>1</gravity>
      <self_collide>1</self_collide>
    </link>
    <joint name='panda_joint5' type='revolute'>
      <pose relative_to='panda_link4'>-0.0825 0.384 0 -1.5708 0 0</pose>
      <parent>panda_link4</parent>
      <child>panda_link5</child>
      <axis>
        <xyz>0 0 1</xyz>
        <limit>
          <lower>-2.9671</lower>
          <upper>2.9671</upper>
          <effort>12</effort>
          <velocity>3</velocity>
        </limit>
        <dynamics>
          <damping>0.003</damping>
          <friction>0</friction>
          <spring_reference>0</spring_reference>
          <spring_stiffness>0</spring_stiffness>
        </dynamics>
      </axis>
      <physics>
        <provide_feedback>1</provide_feedback>
        <ode>
          <limit>
            <cfm>0</cfm>
            <erp>0.2</erp>
          </limit>
          <provide_feedback>1</provide_feedback>
        </ode>
      </physics>
    </joint>
    <link name='panda_link5'>
      <pose relative_to='panda_joint5'>0 0 0 0 -0 0</pose>
      <inertial>
        <pose>-0.008191 0.042932 -0.036213 0 -0 0</pose>
        <mass>1.22588</mass>
        <inertia>
          <ixx>0.0398334</ixx>
          <ixy>-0.00416367</ixy>
          <ixz>-0.00577919</ixz>
          <iyy>0.0279639</iyy>
          <iyz>0.00579813</iyz>
          <izz>0.00585271</izz>
        </inertia>
      </inertial>
      <collision name='panda_link5_collision'>
        <pose>0 0 0 0 -0 0</pose>
        <geometry>
          <mesh>
            <scale>1 1 1</scale>
            <uri>file:///home/junglator/pandora_ws/install/gypsy_robot/share/gypsy_robot/meshes/panda_arm/link5.obj</uri>
          </mesh>
        </geometry>
        <surface>
          <contact>
            <ode/>
          </contact>
          <friction>
            <ode/>
          </friction>
        </surface>
      </collision>
      <visual name='panda_link5_visual'>
        <pose>0 0 0 0 -0 0</pose>
        <geometry>
          <mesh>
            <scale>1 1 1</scale>
            <uri>file:///home/junglator/pandora_ws/install/gypsy_robot/share/gypsy_robot/meshes/panda_arm/link5.obj</uri>
          </mesh>
        </geometry>
        <material>
          <script>
            <name>Gazebo/Orange</name>
            <uri>file://media/materials/scripts/gazebo.material</uri>
          </script>
        </material>
      </visual>
      <gravity>1</gravity>
      <self_collide>1</self_collide>
    </link>
    <joint name='panda_joint6' type='revolute'>
      <pose relative_to='panda_link5'>0 0 0 1.5708 -0 0</pose>
      <parent>panda_link5</parent>
      <child>panda_link6</child>
      <axis>
        <xyz>0 0 1</xyz>
        <limit>
          <lower>-0.0873</lower>
          <upper>3.8223</upper>
          <effort>12</effort>
          <velocity>3</velocity>
        </limit>
        <dynamics>
          <damping>0.003</damping>
          <friction>0</friction>
          <spring_reference>0</spring_reference>
          <spring_stiffness>0</spring_stiffness>
        </dynamics>
      </axis>
      <physics>
        <provide_feedback>1</provide_feedback>
        <ode>
          <limit>
            <cfm>0</cfm>
            <erp>0.2</erp>
          </limit>
          <provide_feedback>1</provide_feedback>
        </ode>
      </physics>
    </joint>
    <link name='panda_link6'>
      <pose relative_to='panda_joint6'>0 0 0 0 -0 0</pose>
      <inertial>
        <pose>0.06055 -0.013508 -0.014649 0 -0 0</pose>
        <mass>1.66602</mass>
        <inertia>
          <ixx>0.00189465</ixx>
          <ixy>3.00857e-05</ixy>
          <ixz>-0.00149173</ixz>
          <iyy>0.00593337</iyy>
          <iyz>0.00115001</iyz>
          <izz>0.00392302</izz>
        </inertia>
      </inertial>
      <collision name='panda_link6_collision'>
        <pose>0 0 0 0 -0 0</pose>
        <geometry>
          <mesh>
            <scale>1 1 1</scale>
            <uri>file:///home/junglator/pandora_ws/install/gypsy_robot/share/gypsy_robot/meshes/panda_arm/link6.obj</uri>
          </mesh>
        </geometry>
        <surface>
          <contact>
            <ode/>
          </contact>
          <friction>
            <ode/>
          </friction>
        </surface>
      </collision>
      <visual name='panda_link6_visual'>
        <pose>0 0 0 0 -0 0</pose>
        <geometry>
          <mesh>
            <scale>1 1 1</scale>
            <uri>file:///home/junglator/pandora_ws/install/gypsy_robot/share/gypsy_robot/meshes/panda_arm/link6.obj</uri>
          </mesh>
        </geometry>
        <material>
          <script>
            <name>$panda_body_color}</name>
            <uri>file://media/materials/scripts/gazebo.material</uri>
          </script>
        </material>
      </visual>
      <gravity>1</gravity>
      <self_collide>1</self_collide>
    </link>
    <joint name='panda_joint7' type='revolute'>
      <pose relative_to='panda_link6'>0.088 0 0 1.5708 -0 0</pose>
      <parent>panda_link6</parent>
      <child>panda_link7</child>
      <axis>
        <xyz>0 0 1</xyz>
        <limit>
          <lower>-2.9671</lower>
          <upper>2.9671</upper>
          <effort>12</effort>
          <velocity>3</velocity>
        </limit>
        <dynamics>
          <damping>0.003</damping>
          <friction>0</friction>
          <spring_reference>0</spring_reference>
          <spring_stiffness>0</spring_stiffness>
        </dynamics>
      </axis>
      <physics>
        <provide_feedback>1</provide_feedback>
        <ode>
          <limit>
            <cfm>0</cfm>
            <erp>0.2</erp>
          </limit>
          <provide_feedback>1</provide_feedback>
        </ode>
      </physics>
    </joint>
    <link name='panda_link7'>
      <pose relative_to='panda_joint7'>0 0 0 0 -0 0</pose>
      <inertial>
        <pose>0.006133 -0.001004 0.075393 0 -0 0</pose>
        <mass>1.52382</mass>
        <inertia>
          <ixx>0.0117324</ixx>
          <ixy>3.46183e-05</ixy>
          <ixz>0.00207874</ixz>
          <iyy>0.0134712</iyy>
          <iyz>-0.000525024</iyz>
          <izz>0.00915873</izz>
        </inertia>
      </inertial>
      <collision name='panda_link7_collision'>
        <pose>0 0 0 0 -0 0</pose>
        <geometry>
          <mesh>
            <scale>1 1 1</scale>
            <uri>file:///home/junglator/pandora_ws/install/gypsy_robot/share/gypsy_robot/meshes/panda_arm/link7.obj</uri>
          </mesh>
        </geometry>
        <surface>
          <contact>
            <ode/>
          </contact>
          <friction>
            <ode/>
          </friction>
        </surface>
      </collision>
      <collision name='panda_link7_fixed_joint_lump__camera_two_collision_1'>
        <pose>0.04 -0.032 0.137 0 -0 0.785398</pose>
        <geometry>
          <mesh>
            <scale>0.001 0.001 0.001</scale>
            <uri>file:///home/junglator/pandora_ws/install/gypsy_robot/share/gypsy_robot/meshes/mobile_bot/realsense.obj</uri>
          </mesh>
        </geometry>
        <surface>
          <contact>
            <ode/>
          </contact>
          <friction>
            <ode/>
          </friction>
        </surface>
      </collision>
      <collision name='panda_link7_fixed_joint_lump__hand_collision_2'>
        <pose>0 0 0.057 0 0 -0.785398</pose>
        <geometry>
          <mesh>
            <scale>1 1 1</scale>
            <uri>file:///home/junglator/pandora_ws/install/gypsy_robot/share/gypsy_robot/meshes/panda_arm/hand.obj</uri>
          </mesh>
        </geometry>
        <surface>
          <contact>
            <ode/>
          </contact>
          <friction>
            <ode/>
          </friction>
        </surface>
      </collision>
      <visual name='panda_link7_visual'>
        <pose>0 0 0 0 -0 0</pose>
        <geometry>
          <mesh>
            <scale>1 1 1</scale>
            <uri>file:///home/junglator/pandora_ws/install/gypsy_robot/share/gypsy_robot/meshes/panda_arm/link7.obj</uri>
          </mesh>
        </geometry>
        <material>
          <script>
            <name>Gazebo/Orange</name>
            <uri>file://media/materials/scripts/gazebo.material</uri>
          </script>
        </material>
      </visual>
      <visual name='panda_link7_fixed_joint_lump__camera_two_visual_1'>
        <pose>0.04 -0.032 0.137 0 -0 0.785398</pose>
        <geometry>
          <mesh>
            <scale>0.001 0.001 0.001</scale>
            <uri>file:///home/junglator/pandora_ws/install/gypsy_robot/share/gypsy_robot/meshes/mobile_bot/realsense.obj</uri>
          </mesh>
        </geometry>
        <material>
          <script>
            <name>Gazebo/FlatBlack</name>
            <uri>file://media/materials/scripts/gazebo.material</uri>
          </script>
        </material>
      </visual>
      <visual name='panda_link7_fixed_joint_lump__hand_visual_2'>
        <pose>0 0 0.057 0 0 -0.785398</pose>
        <geometry>
          <mesh>
            <scale>1 1 1</scale>
            <uri>file:///home/junglator/pandora_ws/install/gypsy_robot/share/gypsy_robot/meshes/panda_arm/hand.obj</uri>
          </mesh>
        </geometry>
        <material>
          <script>
            <name>Gazebo/Orange</name>
            <uri>file://media/materials/scripts/gazebo.material</uri>
          </script>
        </material>
      </visual>
      <gravity>1</gravity>
      <self_collide>1</self_collide>
      <gravity>1</gravity>
      <self_collide>1</self_collide>
      <gravity>1</gravity>
      <self_collide>1</self_collide>
    </link>
    <joint name='finger_joint1' type='prismatic'>
      <pose relative_to='panda_link7'>0 0 0.1154 0 0 -0.785398</pose>
      <parent>panda_link7</parent>
      <child>leftfinger</child>
      <axis>
        <xyz>0 1 0</xyz>
        <limit>
          <lower>-0.001</lower>
          <upper>0.04</upper>
          <effort>20</effort>
          <velocity>0.3</velocity>
        </limit>
        <dynamics>
          <spring_reference>0</spring_reference>
          <spring_stiffness>0</spring_stiffness>
        </dynamics>
      </axis>
    </joint>
    <link name='leftfinger'>
      <pose relative_to='finger_joint1'>0 0 0 0 -0 0</pose>
      <inertial>
        <pose>0 0.014564 0.022794 0 -0 0</pose>
        <mass>0.1</mass>
        <inertia>
          <ixx>3.01221e-05</ixx>
          <ixy>0</ixy>
          <ixz>0</ixz>
          <iyy>2.95874e-05</iyy>
          <iyz>0</iyz>
          <izz>6.95125e-06</izz>
        </inertia>
      </inertial>
      <collision name='leftfinger_collision'>
        <pose>0 0 0 0 -0 0</pose>
        <geometry>
          <mesh>
            <scale>1 1 1</scale>
            <uri>file:///home/junglator/pandora_ws/install/gypsy_robot/share/gypsy_robot/meshes/panda_arm/finger.obj</uri>
          </mesh>
        </geometry>
        <surface>
          <contact>
            <ode/>
          </contact>
          <friction>
            <ode/>
          </friction>
        </surface>
      </collision>
      <visual name='leftfinger_visual'>
        <pose>0 0 0 0 -0 0</pose>
        <geometry>
          <mesh>
            <scale>1 1 1</scale>
            <uri>file:///home/junglator/pandora_ws/install/gypsy_robot/share/gypsy_robot/meshes/panda_arm/finger.obj</uri>
          </mesh>
        </geometry>
        <material>
          <script>
            <name>Gazebo/Black</name>
            <uri>file://media/materials/scripts/gazebo.material</uri>
          </script>
        </material>
      </visual>
      <gravity>1</gravity>
      <self_collide>1</self_collide>
    </link>
    <joint name='finger_joint2' type='prismatic'>
      <pose relative_to='panda_link7'>0 0 0.1154 0 0 -0.785398</pose>
      <parent>panda_link7</parent>
      <child>rightfinger</child>
      <axis>
        <xyz>0 -1 0</xyz>
        <limit>
          <lower>-0.001</lower>
          <upper>0.04</upper>
          <effort>20</effort>
          <velocity>0.3</velocity>
        </limit>
        <dynamics>
          <spring_reference>0</spring_reference>
          <spring_stiffness>0</spring_stiffness>
        </dynamics>
      </axis>
    </joint>
    <link name='rightfinger'>
      <pose relative_to='finger_joint2'>0 0 0 0 -0 0</pose>
      <inertial>
        <pose>0 0.014564 0.022794 0 -0 3.14159</pose>
        <mass>0.1</mass>
        <inertia>
          <ixx>3.01221e-05</ixx>
          <ixy>0</ixy>
          <ixz>0</ixz>
          <iyy>2.95874e-05</iyy>
          <iyz>0</iyz>
          <izz>6.95125e-06</izz>
        </inertia>
      </inertial>
      <collision name='rightfinger_collision'>
        <pose>0 0 0 0 -0 3.14159</pose>
        <geometry>
          <mesh>
            <scale>1 1 1</scale>
            <uri>file:///home/junglator/pandora_ws/install/gypsy_robot/share/gypsy_robot/meshes/panda_arm/finger.obj</uri>
          </mesh>
        </geometry>
        <surface>
          <contact>
            <ode/>
          </contact>
          <friction>
            <ode/>
          </friction>
        </surface>
      </collision>
      <visual name='rightfinger_visual'>
        <pose>0 0 0 0 -0 3.14159</pose>
        <geometry>
          <mesh>
            <scale>1 1 1</scale>
            <uri>file:///home/junglator/pandora_ws/install/gypsy_robot/share/gypsy_robot/meshes/panda_arm/finger.obj</uri>
          </mesh>
        </geometry>
        <material>
          <script>
            <name>Gazebo/Black</name>
            <uri>file://media/materials/scripts/gazebo.material</uri>
          </script>
        </material>
      </visual>
      <gravity>1</gravity>
      <self_collide>1</self_collide>
    </link>
    <joint name='bottom_left_wheel_joint' type='revolute'>
      <pose relative_to='base_footprint'>0.2237 -0.273 0.03 0 -0 1.5708</pose>
      <parent>base_footprint</parent>
      <child>left_bottom_wheel</child>
      <axis>
        <xyz>1 0 0</xyz>
        <limit>
          <lower>-1e+16</lower>
          <upper>1e+16</upper>
        </limit>
        <dynamics>
          <spring_reference>0</spring_reference>
          <spring_stiffness>0</spring_stiffness>
        </dynamics>
      </axis>
    </joint>
    <link name='left_bottom_wheel'>
      <pose relative_to='bottom_left_wheel_joint'>0 0 0 0 -0 0</pose>
      <inertial>
        <pose>0 0 0 0 -0 0</pose>
        <mass>0.329</mass>
        <inertia>
          <ixx>1.29e-05</ixx>
          <ixy>0</ixy>
          <ixz>0</ixz>
          <iyy>8.6529e-05</iyy>
          <iyz>0</iyz>
          <izz>8.6529e-05</izz>
        </inertia>
      </inertial>
      <collision name='left_bottom_wheel_collision'>
        <pose>0 0 0 0 -0 0</pose>
        <geometry>
          <mesh>
            <scale>0.1 0.1 0.1</scale>
            <uri>file:///home/junglator/pandora_ws/install/gypsy_robot/share/gypsy_robot/meshes/mobile_bot/Wheel_Left.obj</uri>
          </mesh>
        </geometry>
        <surface>
          <contact>
            <ode/>
          </contact>
          <friction>
            <ode/>
          </friction>
        </surface>
      </collision>
      <visual name='left_bottom_wheel_visual'>
        <pose>0 0 0 0 -0 0</pose>
        <geometry>
          <mesh>
            <scale>0.1 0.1 0.1</scale>
            <uri>file:///home/junglator/pandora_ws/install/gypsy_robot/share/gypsy_robot/meshes/mobile_bot/Wheel_Left.obj</uri>
          </mesh>
        </geometry>
        <material>
          <script>
            <name>Gazebo/Black</name>
            <uri>file://media/materials/scripts/gazebo.material</uri>
          </script>
        </material>
      </visual>
    </link>
    <joint name='bottom_right_wheel_joint' type='revolute'>
      <pose relative_to='base_footprint'>0.2237 0.273 0.03 0 -0 1.5708</pose>
      <parent>base_footprint</parent>
      <child>right_bottom_wheel</child>
      <axis>
        <xyz>1 0 0</xyz>
        <limit>
          <lower>-1e+16</lower>
          <upper>1e+16</upper>
        </limit>
        <dynamics>
          <spring_reference>0</spring_reference>
          <spring_stiffness>0</spring_stiffness>
        </dynamics>
      </axis>
    </joint>
    <link name='right_bottom_wheel'>
      <pose relative_to='bottom_right_wheel_joint'>0 0 0 0 -0 0</pose>
      <inertial>
        <pose>0 0 0 0 -0 0</pose>
        <mass>0.329</mass>
        <inertia>
          <ixx>1.29e-05</ixx>
          <ixy>0</ixy>
          <ixz>0</ixz>
          <iyy>8.6529e-05</iyy>
          <iyz>0</iyz>
          <izz>8.6529e-05</izz>
        </inertia>
      </inertial>
      <collision name='right_bottom_wheel_collision'>
        <pose>0 0 0 0 -0 0</pose>
        <geometry>
          <mesh>
            <scale>0.1 0.1 0.1</scale>
            <uri>file:///home/junglator/pandora_ws/install/gypsy_robot/share/gypsy_robot/meshes/mobile_bot/Wheel_Right.obj</uri>
          </mesh>
        </geometry>
      </collision>
      <visual name='right_bottom_wheel_visual'>
        <pose>0 0 0 0 -0 0</pose>
        <geometry>
          <mesh>
            <scale>0.1 0.1 0.1</scale>
            <uri>file:///home/junglator/pandora_ws/install/gypsy_robot/share/gypsy_robot/meshes/mobile_bot/Wheel_Right.obj</uri>
          </mesh>
        </geometry>
      </visual>
    </link>
    <joint name='upper_left_wheel_joint' type='revolute'>
      <pose relative_to='base_footprint'>-0.2237 -0.273 0.03 0 -0 1.5708</pose>
      <parent>base_footprint</parent>
      <child>right_upper_wheel</child>
      <axis>
        <xyz>1 0 0</xyz>
        <limit>
          <lower>-1e+16</lower>
          <upper>1e+16</upper>
        </limit>
        <dynamics>
          <spring_reference>0</spring_reference>
          <spring_stiffness>0</spring_stiffness>
        </dynamics>
      </axis>
    </joint>
    <link name='right_upper_wheel'>
      <pose relative_to='upper_left_wheel_joint'>0 0 0 0 -0 0</pose>
      <inertial>
        <pose>0 0 0 0 -0 0</pose>
        <mass>0.329</mass>
        <inertia>
          <ixx>1.29e-05</ixx>
          <ixy>0</ixy>
          <ixz>0</ixz>
          <iyy>8.6529e-05</iyy>
          <iyz>0</iyz>
          <izz>8.6529e-05</izz>
        </inertia>
      </inertial>
      <collision name='right_upper_wheel_collision'>
        <pose>0 0 0 0 -0 0</pose>
        <geometry>
          <mesh>
            <scale>0.1 0.1 0.1</scale>
            <uri>file:///home/junglator/pandora_ws/install/gypsy_robot/share/gypsy_robot/meshes/mobile_bot/Wheel_Right.obj</uri>
          </mesh>
        </geometry>
        <surface>
          <contact>
            <ode/>
          </contact>
          <friction>
            <ode/>
          </friction>
        </surface>
      </collision>
      <visual name='right_upper_wheel_visual'>
        <pose>0 0 0 0 -0 0</pose>
        <geometry>
          <mesh>
            <scale>0.1 0.1 0.1</scale>
            <uri>file:///home/junglator/pandora_ws/install/gypsy_robot/share/gypsy_robot/meshes/mobile_bot/Wheel_Right.obj</uri>
          </mesh>
        </geometry>
        <material>
          <script>
            <name>Gazebo/Black</name>
            <uri>file://media/materials/scripts/gazebo.material</uri>
          </script>
        </material>
      </visual>
    </link>
    <joint name='upper_right_wheel_joint' type='revolute'>
      <pose relative_to='base_footprint'>-0.2237 0.273 0.03 0 -0 1.5708</pose>
      <parent>base_footprint</parent>
      <child>left_upper_wheel</child>
      <axis>
        <xyz>1 0 0</xyz>
        <limit>
          <lower>-1e+16</lower>
          <upper>1e+16</upper>
        </limit>
        <dynamics>
          <spring_reference>0</spring_reference>
          <spring_stiffness>0</spring_stiffness>
        </dynamics>
      </axis>
    </joint>
    <link name='left_upper_wheel'>
      <pose relative_to='upper_right_wheel_joint'>0 0 0 0 -0 0</pose>
      <inertial>
        <pose>0 0 0 0 -0 0</pose>
        <mass>0.329</mass>
        <inertia>
          <ixx>1.29e-05</ixx>
          <ixy>0</ixy>
          <ixz>0</ixz>
          <iyy>8.6529e-05</iyy>
          <iyz>0</iyz>
          <izz>8.6529e-05</izz>
        </inertia>
      </inertial>
      <collision name='left_upper_wheel_collision'>
        <pose>0 0 0 0 -0 0</pose>
        <geometry>
          <mesh>
            <scale>0.1 0.1 0.1</scale>
            <uri>file:///home/junglator/pandora_ws/install/gypsy_robot/share/gypsy_robot/meshes/mobile_bot/Wheel_Left.obj</uri>
          </mesh>
        </geometry>
        <surface>
          <contact>
            <ode/>
          </contact>
          <friction>
            <ode/>
          </friction>
        </surface>
      </collision>
      <visual name='left_upper_wheel_visual'>
        <pose>0 0 0 0 -0 0</pose>
        <geometry>
          <mesh>
            <scale>0.1 0.1 0.1</scale>
            <uri>file:///home/junglator/pandora_ws/install/gypsy_robot/share/gypsy_robot/meshes/mobile_bot/Wheel_Left.obj</uri>
          </mesh>
        </geometry>
        <material>
          <script>
            <name>Gazebo/Black</name>
            <uri>file://media/materials/scripts/gazebo.material</uri>
          </script>
        </material>
      </visual>
    </link>
    <self_collide>1</self_collide>
    <plugin name='gazebo_ros_control' filename='libgazebo_ros_control.so'>
      <robotNamespace>panda</robotNamespace>
      <controlPeriod>0.001</controlPeriod>
      <legacyModeNS>0</legacyModeNS>
    </plugin>
    <plugin name='joint_state_publisher' filename='libgazebo_ros_joint_state_publisher.so'>
      <jointName>panda_joint0,panda_joint1,panda_joint2,panda_joint3,panda_joint4, panda_joint5,panda_joint6,panda_joint7,finger_joint1,finger_joint1</jointName>
    </plugin>
    <plugin name='camera' filename='librealsense_gazebo_plugin.so'>
      <depthUpdateRate>30</depthUpdateRate>
      <colorUpdateRate>30</colorUpdateRate>
      <infraredUpdateRate>30</infraredUpdateRate>
      <depthTopicName>depth/image_raw</depthTopicName>
      <depthCameraInfoTopicName>depth/camera_info</depthCameraInfoTopicName>
      <colorTopicName>color/image_raw</colorTopicName>
      <colorCameraInfoTopicName>color/camera_info</colorCameraInfoTopicName>
      <infrared1TopicName>infrared/image_raw</infrared1TopicName>
      <infrared1CameraInfoTopicName>infrared/camera_info</infrared1CameraInfoTopicName>
      <infrared2TopicName>infrared2/image_raw</infrared2TopicName>
      <infrared2CameraInfoTopicName>infrared2/camera_info</infrared2CameraInfoTopicName>
      <colorOpticalframeName>camera_color_optical_frame</colorOpticalframeName>
      <depthOpticalframeName>camera_depth_optical_frame</depthOpticalframeName>
      <infrared1OpticalframeName>camera_left_ir_optical_frame</infrared1OpticalframeName>
      <infrared2OpticalframeName>camera_right_ir_optical_frame</infrared2OpticalframeName>
      <rangeMinDepth>0.1</rangeMinDepth>
      <rangeMaxDepth>10</rangeMaxDepth>
      <pointCloud>1</pointCloud>
      <pointCloudTopicName>depth/color/points</pointCloudTopicName>
      <pointCloudCutoff>0.15</pointCloudCutoff>
      <pointCloudCutoffMax>10</pointCloudCutoffMax>
    </plugin>
    <static>0</static>
    <plugin name='mecanum_controller' filename='libgazebo_ros_planar_move.so'>
      <commandTopic>cmd_vel</commandTopic>
      <odometryTopic>odom</odometryTopic>
      <odometryFrame>odom</odometryFrame>
      <odometryRate>100.0</odometryRate>
      <update_rate>100</update_rate>
      <publish_rate>10</publish_rate>
      <robotBaseFrame>base_footprint</robotBaseFrame>
      <publishTF>0</publishTF>
      <covariance_x>0.0001</covariance_x>
      <covariance_y>0.0001</covariance_y>
      <covariance_yaw>0.01</covariance_yaw>
    </plugin>
  </model>
</sdf>